Workbook

Sheet _Data_A
A1: x1 | B1: x2 | C1: x5 | D1: x4 | E1: x6 | F1: x9 | G1: x3
A2: 0 | B2: 1 | C2: 1 | D2: 1 | E2: 0 | F2: 2 | G2: 2
A3: 0 | B3: 0 | C3: 0 | D3: 1 | E3: 1 | F3: 3 | G3: 2
A4: 0 | B4: 1 | C4: 1 | D4: 1 | E4: 0 | F4: 2 | G4: 2
A5: 0 | B5: 0 | C5: 0 | D5: 1 | E5: 1 | F5: 3 | G5: 2
A6: 0 | B6: 0 | C6: 0 | D6: 1 | E6: 1 | F6: 3 | G6: 0
A7: 1 | B7: 0 | C7: 2 | D7: 1 | E7: 1 | F7: 3 | G7: 2
A8: 1 | B8: 1 | C8: 0 | D8: 0 | E8: 1 | F8: 1 | G8: 2
A9: 0 | B9: 1 | C9: 1 | D9: 1 | E9: 0 | F9: 2 | G9: 2
A10: 0 | B10: 1 | C10: 1 | D10: 1 | E10: 0 | F10: 2 | G10: 0
A11: 0 | B11: 1 | C11: 1 | D11: 1 | E11: 1 | F11: 3 | G11: 2
A12: 0 | B12: 0 | C12: 0 | D12: 1 | E12: 0 | F12: 2 | G12: 2
A13: 1 | B13: 1 | C13: 0 | D13: 0 | E13: 0 | F13: 0 | G13: 0
... A499: 0 | B499: 1 | C499: 1 | D499: 1 | E499: 1 | F499: 3 | G499: 0

Sheet _Calc_A
A1: CÁLCULOS MI — Dataset A
A2: N = | B2: 498
A4: x1 — x2
A5: x1 | B5: x2 | C5: freq | D5: p(x1,x2) | E5: p(x1) | F5: p(x2) | G5: p(a)·p(b) | H5: ratio | I5: log₂(ratio) | J5: p·log₂(ratio)
A6: 0 | B6: 0 | C6: =COUNTIFS(_Data_A!A:A,0,_Data_A!B:B,0) | D6: =IF(C6=0,0,C6/498) | E6: =IF(C6=0,0,COUNTIF(_Data_A!A:A,0)/498) | F6: =IF(C6=0,0,COUNTIF(_Data_A!B:B,0)/498) | G6: =IF(D6=0,0,E6*F6) | H6: =IF(G6=0,0,D6/G6) | I6: =IF(H6<=0,0,LOG(H6,2)) | J6: =D6*I6
A7: 0 | B7: 1 | C7: =COUNTIFS(_Data_A!A:A,0,_Data_A!B:B,1) | D7: =IF(C7=0,0,C7/498) | E7: =IF(C7=0,0,COUNTIF(_Data_A!A:A,0)/498) | F7: =IF(C7=0,0,COUNTIF(_Data_A!B:B,1)/498) | G7: =IF(D7=0,0,E7*F7) | H7: =IF(G7=0,0,D7/G7) | I7: =IF(H7<=0,0,LOG(H7,2)) | J7: =D7*I7
A8: 1 | B8: 0 | C8: =COUNTIFS(_Data_A!A:A,1,_Data_A!B:B,0) | D8: =IF(C8=0,0,C8/498) | E8: =IF(C8=0,0,COUNTIF(_Data_A!A:A,1)/498) | F8: =IF(C8=0,0,COUNTIF(_Data_A!B:B,0)/498) | G8: =IF(D8=0,0,E8*F8) | H8: =IF(G8=0,0,D8/G8) | I8: =IF(H8<=0,0,LOG(H8,2)) | J8: =D8*I8
A9: 1 | B9: 1 | C9: =COUNTIFS(_Data_A!A:A,1,_Data_A!B:B,1) | D9: =IF(C9=0,0,C9/498) | E9: =IF(C9=0,0,COUNTIF(_Data_A!A:A,1)/498) | F9: =IF(C9=0,0,COUNTIF(_Data_A!B:B,1)/498) | G9: =IF(D9=0,0,E9*F9) | H9: =IF(G9=0,0,D9/G9) | I9: =IF(H9<=0,0,LOG(H9,2)) | J9: =D9*I9
A10: IM(x1,x2) = | J10: =SUM(J6:J9)
A13: x1 — x5
A14: x1 | B14: x5 | C14: freq | D14: p(x1,x5) | E14: p(x1) | F14: p(x5) | G14: p(a)·p(b) | H14: ratio | I14: log₂(ratio) | J14: p·log₂(ratio)
A15: 0 | B15: 0 | C15: =COUNTIFS(_Data_A!A:A,0,_Data_A!C:C,0) | D15: =IF(C15=0,0,C15/498) | E15: =IF(C15=0,0,COUNTIF(_Data_A!A:A,0)/498) | F15: =IF(C15=0,0,COUNTIF(_Data_A!C:C,0)/498) | G15: =IF(D15=0,0,E15*F15) | H15: =IF(G15=0,0,D15/G15) | I15: =IF(H15<=0,0,LOG(H15,2)) | J15: =D15*I15
A16: 0 | B16: 1 | C16: =COUNTIFS(_Data_A!A:A,0,_Data_A!C:C,1) | D16: =IF(C16=0,0,C16/498) | E16: =IF(C16=0,0,COUNTIF(_Data_A!A:A,0)/498) | F16: =IF(C16=0,0,COUNTIF(_Data_A!C:C,1)/498) | G16: =IF(D16=0,0,E16*F16) | H16: =IF(G16=0,0,D16/G16) | I16: =IF(H16<=0,0,LOG(H16,2)) | J16: =D16*I16
A17: 0 | B17: 2 | C17: =COUNTIFS(_Data_A!A:A,0,_Data_A!C:C,2) | D17: =IF(C17=0,0,C17/498) | E17: =IF(C17=0,0,COUNTIF(_Data_A!A:A,0)/498) | F17: =IF(C17=0,0,COUNTIF(_Data_A!C:C,2)/498) | G17: =IF(D17=0,0,E17*F17) | H17: =IF(G17=0,0,D17/G17) | I17: =IF(H17<=0,0,LOG(H17,2)) | J17: =D17*I17
A18: 1 | B18: 0 | C18: =COUNTIFS(_Data_A!A:A,1,_Data_A!C:C,0) | D18: =IF(C18=0,0,C18/498) | E18: =IF(C18=0,0,COUNTIF(_Data_A!A:A,1)/498) | F18: =IF(C18=0,0,COUNTIF(_Data_A!C:C,0)/498) | G18: =IF(D18=0,0,E18*F18) | H18: =IF(G18=0,0,D18/G18) | I18: =IF(H18<=0,0,LOG(H18,2)) | J18: =D18*I18
A19: 1 | B19: 1 | C19: =COUNTIFS(_Data_A!A:A,1,_Data_A!C:C,1) | D19: =IF(C19=0,0,C19/498) | E19: =IF(C19=0,0,COUNTIF(_Data_A!A:A,1)/498) | F19: =IF(C19=0,0,COUNTIF(_Data_A!C:C,1)/498) | G19: =IF(D19=0,0,E19*F19) | H19: =IF(G19=0,0,D19/G19) | I19: =IF(H19<=0,0,LOG(H19,2)) | J19: =D19*I19
A20: 1 | B20: 2 | C20: =COUNTIFS(_Data_A!A:A,1,_Data_A!C:C,2) | D20: =IF(C20=0,0,C20/498) | E20: =IF(C20=0,0,COUNTIF(_Data_A!A:A,1)/498) | F20: =IF(C20=0,0,COUNTIF(_Data_A!C:C,2)/498) | G20: =IF(D20=0,0,E20*F20) | H20: =IF(G20=0,0,D20/G20) | I20: =IF(H20<=0,0,LOG(H20,2)) | J20: =D20*I20
A21: IM(x1,x5) = | J21: =SUM(J15:J20)
A24: x1 — x4
A25: x1 | B25: x4 | C25: freq | D25: p(x1,x4) | E25: p(x1) | F25: p(x4) | G25: p(a)·p(b) | H25: ratio | I25: log₂(ratio) | J25: p·log₂(ratio)
A26: 0 | B26: 0 | C26: =COUNTIFS(_Data_A!A:A,0,_Data_A!D:D,0) | D26: =IF(C26=0,0,C26/498) | E26: =IF(C26=0,0,COUNTIF(_Data_A!A:A,0)/498) | F26: =IF(C26=0,0,COUNTIF(_Data_A!D:D,0)/498) | G26: =IF(D26=0,0,E26*F26) | H26: =IF(G26=0,0,D26/G26) | I26: =IF(H26<=0,0,LOG(H26,2)) | J26: =D26*I26
A27: 0 | B27: 1 | C27: =COUNTIFS(_Data_A!A:A,0,_Data_A!D:D,1) | D27: =IF(C27=0,0,C27/498) | E27: =IF(C27=0,0,COUNTIF(_Data_A!A:A,0)/498) | F27: =IF(C27=0,0,COUNTIF(_Data_A!D:D,1)/498) | G27: =IF(D27=0,0,E27*F27) | H27: =IF(G27=0,0,D27/G27) | I27: =IF(H27<=0,0,LOG(H27,2)) | J27: =D27*I27
A28: 1 | B28: 0 | C28: =COUNTIFS(_Data_A!A:A,1,_Data_A!D:D,0) | D28: =IF(C28=0,0,C28/498) | E28: =IF(C28=0,0,COUNTIF(_Data_A!A:A,1)/498) | F28: =IF(C28=0,0,COUNTIF(_Data_A!D:D,0)/498) | G28: =IF(D28=0,0,E28*F28) | H28: =IF(G28=0,0,D28/G28) | I28: =IF(H28<=0,0,LOG(H28,2)) | J28: =D28*I28
A29: 1 | B29: 1 | C29: =COUNTIFS(_Data_A!A:A,1,_Data_A!D:D,1) | D29: =IF(C29=0,0,C29/498) | E29: =IF(C29=0,0,COUNTIF(_Data_A!A:A,1)/498) | F29: =IF(C29=0,0,COUNTIF(_Data_A!D:D,1)/498) | G29: =IF(D29=0,0,E29*F29) | H29: =IF(G29=0,0,D29/G29) | I29: =IF(H29<=0,0,LOG(H29,2)) | J29: =D29*I29
A30: IM(x1,x4) = | J30: =SUM(J26:J29)
A33: x1 — x6
A34: x1 | B34: x6 | C34: freq | D34: p(x1,x6) | E34: p(x1) | F34: p(x6) | G34: p(a)·p(b) | H34: ratio | I34: log₂(ratio) | J34: p·log₂(ratio)
A35: 0 | B35: 0 | C35: =COUNTIFS(_Data_A!A:A,0,_Data_A!E:E,0) | D35: =IF(C35=0,0,C35/498) | E35: =IF(C35=0,0,COUNTIF(_Data_A!A:A,0)/498) | F35: =IF(C35=0,0,COUNTIF(_Data_A!E:E,0)/498) | G35: =IF(D35=0,0,E35*F35) | H35: =IF(G35=0,0,D35/G35) | I35: =IF(H35<=0,0,LOG(H35,2)) | J35: =D35*I35
A36: 0 | B36: 1 | C36: =COUNTIFS(_Data_A!A:A,0,_Data_A!E:E,1) | D36: =IF(C36=0,0,C36/498) | E36: =IF(C36=0,0,COUNTIF(_Data_A!A:A,0)/498) | F36: =IF(C36=0,0,COUNTIF(_Data_A!E:E,1)/498) | G36: =IF(D36=0,0,E36*F36) | H36: =IF(G36=0,0,D36/G36) | I36: =IF(H36<=0,0,LOG(H36,2)) | J36: =D36*I36
A37: 1 | B37: 0 | C37: =COUNTIFS(_Data_A!A:A,1,_Data_A!E:E,0) | D37: =IF(C37=0,0,C37/498) | E37: =IF(C37=0,0,COUNTIF(_Data_A!A:A,1)/498) | F37: =IF(C37=0,0,COUNTIF(_Data_A!E:E,0)/498) | G37: =IF(D37=0,0,E37*F37) | H37: =IF(G37=0,0,D37/G37) | I37: =IF(H37<=0,0,LOG(H37,2)) | J37: =D37*I37
A38: 1 | B38: 1 | C38: =COUNTIFS(_Data_A!A:A,1,_Data_A!E:E,1) | D38: =IF(C38=0,0,C38/498) | E38: =IF(C38=0,0,COUNTIF(_Data_A!A:A,1)/498) | F38: =IF(C38=0,0,COUNTIF(_Data_A!E:E,1)/498) | G38: =IF(D38=0,0,E38*F38) | H38: =IF(G38=0,0,D38/G38) | I38: =IF(H38<=0,0,LOG(H38,2)) | J38: =D38*I38
A39: IM(x1,x6) = | J39: =SUM(J35:J38)
A42: x1 — x9
A43: x1 | B43: x9 | C43: freq | D43: p(x1,x9) | E43: p(x1) | F43: p(x9) | G43: p(a)·p(b) | H43: ratio | I43: log₂(ratio) | J43: p·log₂(ratio)
A44: 0 | B44: 0 | C44: =COUNTIFS(_Data_A!A:A,0,_Data_A!F:F,0) | D44: =IF(C44=0,0,C44/498) | E44: =IF(C44=0,0,COUNTIF(_Data_A!A:A,0)/498) | F44: =IF(C44=0,0,COUNTIF(_Data_A!F:F,0)/498) | G44: =IF(D44=0,0,E44*F44) | H44: =IF(G44=0,0,D44/G44) | I44: =IF(H44<=0,0,LOG(H44,2)) | J44: =D44*I44
A45: 0 | B45: 1 | C45: =COUNTIFS(_Data_A!A:A,0,_Data_A!F:F,1) | D45: =IF(C45=0,0,C45/498) | E45: =IF(C45=0,0,COUNTIF(_Data_A!A:A,0)/498) | F45: =IF(C45=0,0,COUNTIF(_Data_A!F:F,1)/498) | G45: =IF(D45=0,0,E45*F45) | H45: =IF(G45=0,0,D45/G45) | I45: =IF(H45<=0,0,LOG(H45,2)) | J45: =D45*I45
A46: 0 | B46: 2 | C46: =COUNTIFS(_Data_A!A:A,0,_Data_A!F:F,2) | D46: =IF(C46=0,0,C46/498) | E46: =IF(C46=0,0,COUNTIF(_Data_A!A:A,0)/498) | F46: =IF(C46=0,0,COUNTIF(_Data_A!F:F,2)/498) | G46: =IF(D46=0,0,E46*F46) | H46: =IF(G46=0,0,D46/G46) | I46: =IF(H46<=0,0,LOG(H46,2)) | J46: =D46*I46
A47: 0 | B47: 3 | C47: =COUNTIFS(_Data_A!A:A,0,_Data_A!F:F,3) | D47: =IF(C47=0,0,C47/498) | E47: =IF(C47=0,0,COUNTIF(_Data_A!A:A,0)/498) | F47: =IF(C47=0,0,COUNTIF(_Data_A!F:F,3)/498) | G47: =IF(D47=0,0,E47*F47) | H47: =IF(G47=0,0,D47/G47) | I47: =IF(H47<=0,0,LOG(H47,2)) | J47: =D47*I47
A48: 1 | B48: 0 | C48: =COUNTIFS(_Data_A!A:A,1,_Data_A!F:F,0) | D48: =IF(C48=0,0,C48/498) | E48: =IF(C48=0,0,COUNTIF(_Data_A!A:A,1)/498) | F48: =IF(C48=0,0,COUNTIF(_Data_A!F:F,0)/498) | G48: =IF(D48=0,0,E48*F48) | H48: =IF(G48=0,0,D48/G48) | I48: =IF(H48<=0,0,LOG(H48,2)) | J48: =D48*I48
A49: 1 | B49: 1 | C49: =COUNTIFS(_Data_A!A:A,1,_Data_A!F:F,1) | D49: =IF(C49=0,0,C49/498) | E49: =IF(C49=0,0,COUNTIF(_Data_A!A:A,1)/498) | F49: =IF(C49=0,0,COUNTIF(_Data_A!F:F,1)/498) | G49: =IF(D49=0,0,E49*F49) | H49: =IF(G49=0,0,D49/G49) | I49: =IF(H49<=0,0,LOG(H49,2)) | J49: =D49*I49
...

Sheet A-Entropias
A1: Dataset A — Entropía de Shannon
A2: Registros: 498
A4: H(x1)
A5: Valor (x) | B5: Frecuencia | C5: p(x) | D5: -log₂(p(x)) | E5: -p(x)·log₂(p(x))
A6: 0 | B6: =COUNTIF(_Data_A!A:A,0) | C6: =B6/498 | D6: =IF(C6=0,0,-LOG(C6,2)) | E6: =IF(C6=0,0,-C6*LOG(C6,2))
A7: 1 | B7: =COUNTIF(_Data_A!A:A,1) | C7: =B7/498 | D7: =IF(C7=0,0,-LOG(C7,2)) | E7: =IF(C7=0,0,-C7*LOG(C7,2))
A8: Total | B8: =SUM(B6:B7) | C8: 1 | D8: H(x1) = | E8: =SUM(E6:E7)
A11: H(x2)
A12: Valor (x) | B12: Frecuencia | C12: p(x) | D12: -log₂(p(x)) | E12: -p(x)·log₂(p(x))
A13: 0 | B13: =COUNTIF(_Data_A!B:B,0) | C13: =B13/498 | D13: =IF(C13=0,0,-LOG(C13,2)) | E13: =IF(C13=0,0,-C13*LOG(C13,2))
A14: 1 | B14: =COUNTIF(_Data_A!B:B,1) | C14: =B14/498 | D14: =IF(C14=0,0,-LOG(C14,2)) | E14: =IF(C14=0,0,-C14*LOG(C14,2))
A15: Total | B15: =SUM(B13:B14) | C15: 1 | D15: H(x2) = | E15: =SUM(E13:E14)
A18: H(x5)
A19: Valor (x) | B19: Frecuencia | C19: p(x) | D19: -log₂(p(x)) | E19: -p(x)·log₂(p(x))
A20: 0 | B20: =COUNTIF(_Data_A!C:C,0) | C20: =B20/498 | D20: =IF(C20=0,0,-LOG(C20,2)) | E20: =IF(C20=0,0,-C20*LOG(C20,2))
A21: 1 | B21: =COUNTIF(_Data_A!C:C,1) | C21: =B21/498 | D21: =IF(C21=0,0,-LOG(C21,2)) | E21: =IF(C21=0,0,-C21*LOG(C21,2))
A22: 2 | B22: =COUNTIF(_Data_A!C:C,2) | C22: =B22/498 | D22: =IF(C22=0,0,-LOG(C22,2)) | E22: =IF(C22=0,0,-C22*LOG(C22,2))
A23: Total | B23: =SUM(B20:B22) | C23: 1 | D23: H(x5) = | E23: =SUM(E20:E22)
A26: H(x4)
A27: Valor (x) | B27: Frecuencia | C27: p(x) | D27: -log₂(p(x)) | E27: -p(x)·log₂(p(x))
A28: 0 | B28: =COUNTIF(_Data_A!D:D,0) | C28: =B28/498 | D28: =IF(C28=0,0,-LOG(C28,2)) | E28: =IF(C28=0,0,-C28*LOG(C28,2))
A29: 1 | B29: =COUNTIF(_Data_A!D:D,1) | C29: =B29/498 | D29: =IF(C29=0,0,-LOG(C29,2)) | E29: =IF(C29=0,0,-C29*LOG(C29,2))
A30: Total | B30: =SUM(B28:B29) | C30: 1 | D30: H(x4) = | E30: =SUM(E28:E29)
A33: H(x6)
A34: Valor (x) | B34: Frecuencia | C34: p(x) | D34: -log₂(p(x)) | E34: -p(x)·log₂(p(x))
A35: 0 | B35: =COUNTIF(_Data_A!E:E,0) | C35: =B35/498 | D35: =IF(C35=0,0,-LOG(C35,2)) | E35: =IF(C35=0,0,-C35*LOG(C35,2))
A36: 1 | B36: =COUNTIF(_Data_A!E:E,1) | C36: =B36/498 | D36: =IF(C36=0,0,-LOG(C36,2)) | E36: =IF(C36=0,0,-C36*LOG(C36,2))
A37: Total | B37: =SUM(B35:B36) | C37: 1 | D37: H(x6) = | E37: =SUM(E35:E36)
A40: H(x9)
A41: Valor (x) | B41: Frecuencia | C41: p(x) | D41: -log₂(p(x)) | E41: -p(x)·log₂(p(x))
A42: 0 | B42: =COUNTIF(_Data_A!F:F,0) | C42: =B42/498 | D42: =IF(C42=0,0,-LOG(C42,2)) | E42: =IF(C42=0,0,-C42*LOG(C42,2))
A43: 1 | B43: =COUNTIF(_Data_A!F:F,1) | C43: =B43/498 | D43: =IF(C43=0,0,-LOG(C43,2)) | E43: =IF(C43=0,0,-C43*LOG(C43,2))
A44: 2 | B44: =COUNTIF(_Data_A!F:F,2) | C44: =B44/498 | D44: =IF(C44=0,0,-LOG(C44,2)) | E44: =IF(C44=0,0,-C44*LOG(C44,2))
A45: 3 | B45: =COUNTIF(_Data_A!F:F,3) | C45: =B45/498 | D45: =IF(C45=0,0,-LOG(C45,2)) | E45: =IF(C45=0,0,-C45*LOG(C45,2))
A46: Total | B46: =SUM(B42:B45) | C46: 1 | D46: H(x9) = | E46: =SUM(E42:E45)
A49: H(x3)
A50: Valor (x) | B50: Frecuencia | C50: p(x) | D50: -log₂(p(x)) | E50: -p(x)·log₂(p(x))
A51: 0 | B51: =COUNTIF(_Data_A!G:G,0) | C51: =B51/498 | D51: =IF(C51=0,0,-LOG(C51,2)) | E51: =IF(C51=0,0,-C51*LOG(C51,2))
A52: 2 | B52: =COUNTIF(_Data_A!G:G,2) | C52: =B52/498 | D52: =IF(C52=0,0,-LOG(C52,2)) | E52: =IF(C52=0,0,-C52*LOG(C52,2))
A53: Total | B53: =SUM(B51:B52) | C53: 1 | D53: H(x3) = | E53: =SUM(E51:E52)

Sheet A-Matriz MI
A1: Dataset A — Matriz de Información Mutua
A3: IM(X,Y) | B3: x1 | C3: x2 | D3: x5 | E3: x4 | F3: x6 | G3: x9 | H3: x3
A4: x1 | B4: 0 | C4: =_Calc_A!J10 | D4: =_Calc_A!J21 | E4: =_Calc_A!J30 | F4: =_Calc_A!J39 | G4: =_Calc_A!J52 | H4: =_Calc_A!J61
A5: x2 | B5: =_Calc_A!J10 | C5: 0 | D5: =_Calc_A!J72 | E5: =_Calc_A!J81 | F5: =_Calc_A!J90 | G5: =_Calc_A!J103 | H5: =_Calc_A!J112
A6: x5 | B6: =_Calc_A!J21 | C6: =_Calc_A!J72 | D6: 0 | E6: =_Calc_A!J123 | F6: =_Calc_A!J134 | G6: =_Calc_A!J151 | H6: =_Calc_A!J162
A7: x4 | B7: =_Calc_A!J30 | C7: =_Calc_A!J81 | D7: =_Calc_A!J123 | E7: 0 | F7: =_Calc_A!J171 | G7: =_Calc_A!J184 | H7: =_Calc_A!J193
A8: x6 | B8: =_Calc_A!J39 | C8: =_Calc_A!J90 | D8: =_Calc_A!J134 | E8: =_Calc_A!J171 | F8: 0 | G8: =_Calc_A!J206 | H8: =_Calc_A!J215
A9: x9 | B9: =_Calc_A!J52 | C9: =_Calc_A!J103 | D9: =_Calc_A!J151 | E9: =_Calc_A!J184 | F9: =_Calc_A!J206 | G9: 0 | H9: =_Calc_A!J228
A10: x3 | B10: =_Calc_A!J61 | C10: =_Calc_A!J112 | D10: =_Calc_A!J162 | E10: =_Calc_A!J193 | F10: =_Calc_A!J215 | G10: =_Calc_A!J228 | H10: 0

Sheet A-MI Detalle (x1-x5)
A1: Dataset A — Cálculo Detallado IM(x1,x5)
A3: Tabla de Probabilidades Conjuntas
A5: x1 | B5: x5 | C5: Frecuencia | D5: p(x1,x5) | E5: p(x1) | F5: p(x5) | G5: p/(px·py) | H5: log₂(ratio) | I5: p·log₂(ratio)
A6: 0 | B6: 0 | C6: =COUNTIFS(_Data_A!A:A,0,_Data_A!C:C,0) | D6: =C6/498 | E6: =IF(D6=0,0,COUNTIF(_Data_A!A:A,0)/498) | F6: =IF(D6=0,0,COUNTIF(_Data_A!C:C,0)/498) | G6: =IF(D6=0,0,D6/(E6*F6)) | H6: =IF(G6<=0,0,LOG(G6,2)) | I6: =D6*H6
A7: 0 | B7: 1 | C7: =COUNTIFS(_Data_A!A:A,0,_Data_A!C:C,1) | D7: =C7/498 | E7: =IF(D7=0,0,COUNTIF(_Data_A!A:A,0)/498) | F7: =IF(D7=0,0,COUNTIF(_Data_A!C:C,1)/498) | G7: =IF(D7=0,0,D7/(E7*F7)) | H7: =IF(G7<=0,0,LOG(G7,2)) | I7: =D7*H7
A8: 0 | B8: 2 | C8: =COUNTIFS(_Data_A!A:A,0,_Data_A!C:C,2) | D8: =C8/498 | E8: =IF(D8=0,0,COUNTIF(_Data_A!A:A,0)/498) | F8: =IF(D8=0,0,COUNTIF(_Data_A!C:C,2)/498) | G8: =IF(D8=0,0,D8/(E8*F8)) | H8: =IF(G8<=0,0,LOG(G8,2)) | I8: =D8*H8
A9: 1 | B9: 0 | C9: =COUNTIFS(_Data_A!A:A,1,_Data_A!C:C,0) | D9: =C9/498 | E9: =IF(D9=0,0,COUNTIF(_Data_A!A:A,1)/498) | F9: =IF(D9=0,0,COUNTIF(_Data_A!C:C,0)/498) | G9: =IF(D9=0,0,D9/(E9*F9)) | H9: =IF(G9<=0,0,LOG(G9,2)) | I9: =D9*H9
A10: 1 | B10: 1 | C10: =COUNTIFS(_Data_A!A:A,1,_Data_A!C:C,1) | D10: =C10/498 | E10: =IF(D10=0,0,COUNTIF(_Data_A!A:A,1)/498) | F10: =IF(D10=0,0,COUNTIF(_Data_A!C:C,1)/498) | G10: =IF(D10=0,0,D10/(E10*F10)) | H10: =IF(G10<=0,0,LOG(G10,2)) | I10: =D10*H10
A11: 1 | B11: 2 | C11: =COUNTIFS(_Data_A!A:A,1,_Data_A!C:C,2) | D11: =C11/498 | E11: =IF(D11=0,0,COUNTIF(_Data_A!A:A,1)/498) | F11: =IF(D11=0,0,COUNTIF(_Data_A!C:C,2)/498) | G11: =IF(D11=0,0,D11/(E11*F11)) | H11: =IF(G11<=0,0,LOG(G11,2)) | I11: =D11*H11
E12: IM(x1,x5) = Σ | I12: =SUM(I6:I11)

Sheet A-Kruskal
A1: Dataset A — Algoritmo de Kruskal (MST)
F2: comp(x1) | G2: comp(x2) | H2: comp(x5) | I2: comp(x4) | J2: comp(x6) | K2: comp(x9) | L2: comp(x3)
A3: # | B3: Arista | C3: Peso IM | D3: Decisión | E3: Justificación | F3: x1 | G3: x2 | H3: x5 | I3: x4 | J3: x6 | K3: x9 | L3: x3 | M3: comp(u) | N3: comp(v) | O3: Acum
A4: 1 | B4: x6 — x9 | C4: ='A-Matriz MI'!G9 | D4: =IF(M4=N4,"Rechazado","Aceptado") | E4: =IF(D4="Aceptado","","Ciclo: x6 y x9 ya conectados") | F4: 1 | G4: 2 | H4: 3 | I4: 4 | J4: 5 | K4: 6 | L4: 7 | M4: =J4 | N4: =K4 | O4: =IF(D4="Aceptado",C4,0)
A5: 2 | B5: x2 — x5 | C5: ='A-Matriz MI'!D6 | D5: =IF(M5=N5,"Rechazado","Aceptado") | E5: =IF(D5="Aceptado","","Ciclo: x2 y x5 ya conectados") | F5: =IF(D4="Aceptado",IF(F4=N4,M4,F4),F4) | G5: =IF(D4="Aceptado",IF(G4=N4,M4,G4),G4) | H5: =IF(D4="Aceptado",IF(H4=N4,M4,H4),H4) | I5: =IF(D4="Aceptado",IF(I4=N4,M4,I4),I4) | J5: =IF(D4="Aceptado",IF(J4=N4,M4,J4),J4) | K5: =IF(D4="Aceptado",IF(K4=N4,M4,K4),K4) | L5: =IF(D4="Aceptado",IF(L4=N4,M4,L4),L4) | M5: =G5 | N5: =H5 | O5: =IF(D5="Aceptado",O4+C5,O4)
A6: 3 | B6: x4 — x9 | C6: ='A-Matriz MI'!G8 | D6: =IF(M6=N6,"Rechazado","Aceptado") | E6: =IF(D6="Aceptado","","Ciclo: x4 y x9 ya conectados") | F6: =IF(D5="Aceptado",IF(F5=N5,M5,F5),F5) | G6: =IF(D5="Aceptado",IF(G5=N5,M5,G5),G5) | H6: =IF(D5="Aceptado",IF(H5=N5,M5,H5),H5) | I6: =IF(D5="Aceptado",IF(I5=N5,M5,I5),I5) | J6: =IF(D5="Aceptado",IF(J5=N5,M5,J5),J5) | K6: =IF(D5="Aceptado",IF(K5=N5,M5,K5),K5) | L6: =IF(D5="Aceptado",IF(L5=N5,M5,L5),L5) | M6: =I6 | N6: =K6 | O6: =IF(D6="Aceptado",O5+C6,O5)
A7: 4 | B7: x1 — x5 | C7: ='A-Matriz MI'!D5 | D7: =IF(M7=N7,"Rechazado","Aceptado") | E7: =IF(D7="Aceptado","","Ciclo: x1 y x5 ya conectados") | F7: =IF(D6="Aceptado",IF(F6=N6,M6,F6),F6) | G7: =IF(D6="Aceptado",IF(G6=N6,M6,G6),G6) | H7: =IF(D6="Aceptado",IF(H6=N6,M6,H6),H6) | I7: =IF(D6="Aceptado",IF(I6=N6,M6,I6),I6) | J7: =IF(D6="Aceptado",IF(J6=N6,M6,J6),J6) | K7: =IF(D6="Aceptado",IF(K6=N6,M6,K6),K6) | L7: =IF(D6="Aceptado",IF(L6=N6,M6,L6),L6) | M7: =F7 | N7: =H7 | O7: =IF(D7="Aceptado",O6+C7,O6)
A8: 5 | B8: x5 — x9 | C8: ='A-Matriz MI'!G7 | D8: =IF(M8=N8,"Rechazado","Aceptado") | E8: =IF(D8="Aceptado","","Ciclo: x5 y x9 ya conectados") | F8: =IF(D7="Aceptado",IF(F7=N7,M7,F7),F7) | G8: =IF(D7="Aceptado",IF(G7=N7,M7,G7),G7) | H8: =IF(D7="Aceptado",IF(H7=N7,M7,H7),H7) | I8: =IF(D7="Aceptado",IF(I7=N7,M7,I7),I7) | J8: =IF(D7="Aceptado",IF(J7=N7,M7,J7),J7) | K8: =IF(D7="Aceptado",IF(K7=N7,M7,K7),K7) | L8: =IF(D7="Aceptado",IF(L7=N7,M7,L7),L7) | M8: =H8 | N8: =K8 | O8: =IF(D8="Aceptado",O7+C8,O7)
A9: 6 | B9: x1 — x2 | C9: ='A-Matriz MI'!C5 | D9: =IF(M9=N9,"Rechazado","Aceptado") | E9: =IF(D9="Aceptado","","Ciclo: x1 y x2 ya conectados") | F9: =IF(D8="Aceptado",IF(F8=N8,M8,F8),F8) | G9: =IF(D8="Aceptado",IF(G8=N8,M8,G8),G8) | H9: =IF(D8="Aceptado",IF(H8=N8,M8,H8),H8) | I9: =IF(D8="Aceptado",IF(I8=N8,M8,I8),I8) | J9: =IF(D8="Aceptado",IF(J8=N8,M8,J8),J8) | K9: =IF(D8="Aceptado",IF(K8=N8,M8,K8),K8) | L9: =IF(D8="Aceptado",IF(L8=N8,M8,L8),L8) | M9: =F9 | N9: =G9 | O9: =IF(D9="Aceptado",O8+C9,O8)
A10: 7 | B10: x9 — x3 | C10: ='A-Matriz MI'!H10 | D10: =IF(M10=N10,"Rechazado","Aceptado") | E10: =IF(D10="Aceptado","","Ciclo: x9 y x3 ya conectados") | F10: =IF(D9="Aceptado",IF(F9=N9,M9,F9),F9) | G10: =IF(D9="Aceptado",IF(G9=N9,M9,G9),G9) | H10: =IF(D9="Aceptado",IF(H9=N9,M9,H9),H9) | I10: =IF(D9="Aceptado",IF(I9=N9,M9,I9),I9) | J10: =IF(D9="Aceptado",IF(J9=N9,M9,J9),J9) | K10: =IF(D9="Aceptado",IF(K9=N9,M9,K9),K9) | L10: =IF(D9="Aceptado",IF(L9=N9,M9,L9),L9) | M10: =K10 | N10: =L10 | O10: =IF(D10="Aceptado",O9+C10,O9)
A11: 8 | B11: x4 — x3 | C11: ='A-Matriz MI'!H8 | D11: =IF(M11=N11,"Rechazado","Aceptado") | E11: =IF(D11="Aceptado","","Ciclo: x4 y x3 ya conectados") | F11: =IF(D10="Aceptado",IF(F10=N10,M10,F10),F10) | G11: =IF(D10="Aceptado",IF(G10=N10,M10,G10),G10) | H11: =IF(D10="Aceptado",IF(H10=N10,M10,H10),H10) | I11: =IF(D10="Aceptado",IF(I10=N10,M10,I10),I10) | J11: =IF(D10="Aceptado",IF(J10=N10,M10,J10),J10) | K11: =IF(D10="Aceptado",IF(K10=N10,M10,K10),K10) | L11: =IF(D10="Aceptado",IF(L10=N10,M10,L10),L10) | M11: =I11 | N11: =L11 | O11: =IF(D11="Aceptado",O10+C11,O10)
A12: 9 | B12: x2 — x9 | C12: ='A-Matriz MI'!G6 | D12: =IF(M12=N12,"Rechazado","Aceptado") | E12: =IF(D12="Aceptado","","Ciclo: x2 y x9 ya conectados") | F12: =IF(D11="Aceptado",IF(F11=N11,M11,F11),F11) | G12: =IF(D11="Aceptado",IF(G11=N11,M11,G11),G11) | H12: =IF(D11="Aceptado",IF(H11=N11,M11,H11),H11) | I12: =IF(D11="Aceptado",IF(I11=N11,M11,I11),I11) | J12: =IF(D11="Aceptado",IF(J11=N11,M11,J11),J11) | K12: =IF(D11="Aceptado",IF(K11=N11,M11,K11),K11) | L12: =IF(D11="Aceptado",IF(L11=N11,M11,L11),L11) | M12: =G12 | N12: =K12 | O12: =IF(D12="Aceptado",O11+C12,O11)
A13: 10 | B13: x1 — x9 | C13: ='A-Matriz MI'!G5 | D13: =IF(M13=N13,"Rechazado","Aceptado") | E13: =IF(D13="Aceptado","","Ciclo: x1 y x9 ya conectados") | F13: =IF(D12="Aceptado",IF(F12=N12,M12,F12),F12) | G13: =IF(D12="Aceptado",IF(G12=N12,M12,G12),G12) | H13: =IF(D12="Aceptado",IF(H12=N12,M12,H12),H12) | I13: =IF(D12="Aceptado",IF(I12=N12,M12,I12),I12) | J13: =IF(D12="Aceptado",IF(J12=N12,M12,J12),J12) | K13: =IF(D12="Aceptado",IF(K12=N12,M12,K12),K12) | L13: =IF(D12="Aceptado",IF(L12=N12,M12,L12),L12) | M13: =F13 | N13: =K13 | O13: =IF(D13="Aceptado",O12+C13,O12)
A14: 11 | B14: x1 — x4 | C14: ='A-Matriz MI'!E5 | D14: =IF(M14=N14,"Rechazado","Aceptado") | E14: =IF(D14="Aceptado","","Ciclo: x1 y x4 ya conectados") | F14: =IF(D13="Aceptado",IF(F13=N13,M13,F13),F13) | G14: =IF(D13="Aceptado",IF(G13=N13,M13,G13),G13) | H14: =IF(D13="Aceptado",IF(H13=N13,M13,H13),H13) | I14: =IF(D13="Aceptado",IF(I13=N13,M13,I13),I13) | J14: =IF(D13="Aceptado",IF(J13=N13,M13,J13),J13) | K14: =IF(D13="Aceptado",IF(K13=N13,M13,K13),K13) | L14: =IF(D13="Aceptado",IF(L13=N13,M13,L13),L13) | M14: =F14 | N14: =I14 | O14: =IF(D14="Aceptado",O13+C14,O13)
A15: 12 | B15: x5 — x3 | C15: ='A-Matriz MI'!H7 | D15: =IF(M15=N15,"Rechazado","Aceptado") | E15: =IF(D15="Aceptado","","Ciclo: x5 y x3 ya conectados") | F15: =IF(D14="Aceptado",IF(F14=N14,M14,F14),F14) | G15: =IF(D14="Aceptado",IF(G14=N14,M14,G14),G14) | H15: =IF(D14="Aceptado",IF(H14=N14,M14,H14),H14) | I15: =IF(D14="Aceptado",IF(I14=N14,M14,I14),I14) | J15: =IF(D14="Aceptado",IF(J14=N14,M14,J14),J14) | K15: =IF(D14="Aceptado",IF(K14=N14,M14,K14),K14) | L15: =IF(D14="Aceptado",IF(L14=N14,M14,L14),L14) | M15: =H15 | N15: =L15 | O15: =IF(D15="Aceptado",O14+C15,O14)
A16: 13 | B16: x5 — x4 | C16: ='A-Matriz MI'!E7 | D16: =IF(M16=N16,"Rechazado","Aceptado") | E16: =IF(D16="Aceptado","","Ciclo: x5 y x4 ya conectados") | F16: =IF(D15="Aceptado",IF(F15=N15,M15,F15),F15) | G16: =IF(D15="Aceptado",IF(G15=N15,M15,G15),G15) | H16: =IF(D15="Aceptado",IF(H15=N15,M15,H15),H15) | I16: =IF(D15="Aceptado",IF(I15=N15,M15,I15),I15) | J16: =IF(D15="Aceptado",IF(J15=N15,M15,J15),J15) | K16: =IF(D15="Aceptado",IF(K15=N15,M15,K15),K15) | L16: =IF(D15="Aceptado",IF(L15=N15,M15,L15),L15) | M16: =H16 | N16: =I16 | O16: =IF(D16="Aceptado",O15+C16,O15)
A17: 14 | B17: x5 — x6 | C17: ='A-Matriz MI'!F7 | D17: =IF(M17=N17,"Rechazado","Aceptado") | E17: =IF(D17="Aceptado","","Ciclo: x5 y x6 ya conectados") | F17: =IF(D16="Aceptado",IF(F16=N16,M16,F16),F16) | G17: =IF(D16="Aceptado",IF(G16=N16,M16,G16),G16) | H17: =IF(D16="Aceptado",IF(H16=N16,M16,H16),H16) | I17: =IF(D16="Aceptado",IF(I16=N16,M16,I16),I16) | J17: =IF(D16="Aceptado",IF(J16=N16,M16,J16),J16) | K17: =IF(D16="Aceptado",IF(K16=N16,M16,K16),K16) | L17: =IF(D16="Aceptado",IF(L16=N16,M16,L16),L16) | M17: =H17 | N17: =J17 | O17: =IF(D17="Aceptado",O16+C17,O16)
A18: 15 | B18: x2 — x3 | C18: ='A-Matriz MI'!H6 | D18: =IF(M18=N18,"Rechazado","Aceptado") | E18: =IF(D18="Aceptado","","Ciclo: x2 y x3 ya conectados") | F18: =IF(D17="Aceptado",IF(F17=N17,M17,F17),F17) | G18: =IF(D17="Aceptado",IF(G17=N17,M17,G17),G17) | H18: =IF(D17="Aceptado",IF(H17=N17,M17,H17),H17) | I18: =IF(D17="Aceptado",IF(I17=N17,M17,I17),I17) | J18: =IF(D17="Aceptado",IF(J17=N17,M17,J17),J17) | K18: =IF(D17="Aceptado",IF(K17=N17,M17,K17),K17) | L18: =IF(D17="Aceptado",IF(L17=N17,M17,L17),L17) | M18: =G18 | N18: =L18 | O18: =IF(D18="Aceptado",O17+C18,O17)
A19: 16 | B19: x1 — x3 | C19: ='A-Matriz MI'!H5 | D19: =IF(M19=N19,"Rechazado","Aceptado") | E19: =IF(D19="Aceptado","","Ciclo: x1 y x3 ya conectados") | F19: =IF(D18="Aceptado",IF(F18=N18,M18,F18),F18) | G19: =IF(D18="Aceptado",IF(G18=N18,M18,G18),G18) | H19: =IF(D18="Aceptado",IF(H18=N18,M18,H18),H18) | I19: =IF(D18="Aceptado",IF(I18=N18,M18,I18),I18) | J19: =IF(D18="Aceptado",IF(J18=N18,M18,J18),J18) | K19: =IF(D18="Aceptado",IF(K18=N18,M18,K18),K18) | L19: =IF(D18="Aceptado",IF(L18=N18,M18,L18),L18) | M19: =F19 | N19: =L19 | O19: =IF(D19="Aceptado",O18+C19,O18)
A20: 17 | B20: x4 — x6 | C20: ='A-Matriz MI'!F8 | D20: =IF(M20=N20,"Rechazado","Aceptado") | E20: =IF(D20="Aceptado","","Ciclo: x4 y x6 ya conectados") | F20: =IF(D19="Aceptado",IF(F19=N19,M19,F19),F19) | G20: =IF(D19="Aceptado",IF(G19=N19,M19,G19),G19) | H20: =IF(D19="Aceptado",IF(H19=N19,M19,H19),H19) | I20: =IF(D19="Aceptado",IF(I19=N19,M19,I19),I19) | J20: =IF(D19="Aceptado",IF(J19=N19,M19,J19),J19) | K20: =IF(D19="Aceptado",IF(K19=N19,M19,K19),K19) | L20: =IF(D19="Aceptado",IF(L19=N19,M19,L19),L19) | M20: =I20 | N20: =J20 | O20: =IF(D20="Aceptado",O19+C20,O19)
A21: 18 | B21: x1 — x6 | C21: ='A-Matriz MI'!F5 | D21: =IF(M21=N21,"Rechazado","Aceptado") | E21: =IF(D21="Aceptado","","Ciclo: x1 y x6 ya conectados") | F21: =IF(D20="Aceptado",IF(F20=N20,M20,F20),F20) | G21: =IF(D20="Aceptado",IF(G20=N20,M20,G20),G20) | H21: =IF(D20="Aceptado",IF(H20=N20,M20,H20),H20) | I21: =IF(D20="Aceptado",IF(I20=N20,M20,I20),I20) | J21: =IF(D20="Aceptado",IF(J20=N20,M20,J20),J20) | K21: =IF(D20="Aceptado",IF(K20=N20,M20,K20),K20) | L21: =IF(D20="Aceptado",IF(L20=N20,M20,L20),L20) | M21: =F21 | N21: =J21 | O21: =IF(D21="Aceptado",O20+C21,O20)
A22: 19 | B22: x6 — x3 | C22: ='A-Matriz MI'!H9 | D22: =IF(M22=N22,"Rechazado","Aceptado") | E22: =IF(D22="Aceptado","","Ciclo: x6 y x3 ya conectados") | F22: =IF(D21="Aceptado",IF(F21=N21,M21,F21),F21) | G22: =IF(D21="Aceptado",IF(G21=N21,M21,G21),G21) | H22: =IF(D21="Aceptado",IF(H21=N21,M21,H21),H21) | I22: =IF(D21="Aceptado",IF(I21=N21,M21,I21),I21) | J22: =IF(D21="Aceptado",IF(J21=N21,M21,J21),J21) | K22: =IF(D21="Aceptado",IF(K21=N21,M21,K21),K21) | L22: =IF(D21="Aceptado",IF(L21=N21,M21,L21),L21) | M22: =J22 | N22: =L22 | O22: =IF(D22="Aceptado",O21+C22,O21)
A23: 20 | B23: x2 — x6 | C23: ='A-Matriz MI'!F6 | D23: =IF(M23=N23,"Rechazado","Aceptado") | E23: =IF(D23="Aceptado","","Ciclo: x2 y x6 ya conectados") | F23: =IF(D22="Aceptado",IF(F22=N22,M22,F22),F22) | G23: =IF(D22="Aceptado",IF(G22=N22,M22,G22),G22) | H23: =IF(D22="Aceptado",IF(H22=N22,M22,H22),H22) | I23: =IF(D22="Aceptado",IF(I22=N22,M22,I22),I22) | J23: =IF(D22="Aceptado",IF(J22=N22,M22,J22),J22) | K23: =IF(D22="Aceptado",IF(K22=N22,M22,K22),K22) | L23: =IF(D22="Aceptado",IF(L22=N22,M22,L22),L22) | M23: =G23 | N23: =J23 | O23: =IF(D23="Aceptado",O22+C23,O22)
A24: 21 | B24: x2 — x4 | C24: ='A-Matriz MI'!E6 | D24: =IF(M24=N24,"Rechazado","Aceptado") | E24: =IF(D24="Aceptado","","Ciclo: x2 y x4 ya conectados") | F24: =IF(D23="Aceptado",IF(F23=N23,M23,F23),F23) | G24: =IF(D23="Aceptado",IF(G23=N23,M23,G23),G23) | H24: =IF(D23="Aceptado",IF(H23=N23,M23,H23),H23) | I24: =IF(D23="Aceptado",IF(I23=N23,M23,I23),I23) | J24: =IF(D23="Aceptado",IF(J23=N23,M23,J23),J23) | K24: =IF(D23="Aceptado",IF(K23=N23,M23,K23),K23) | L24: =IF(D23="Aceptado",IF(L23=N23,M23,L23),L23) | M24: =G24 | N24: =I24 | O24: =IF(D24="Aceptado",O23+C24,O23)

Sheet A-Prim
A1: Dataset A — Algoritmo de Prim (desde x5)
A3: Paso | B3: Arista | C3: Peso IM | D3: Origen→Destino | E3: Visitados | F3: Acum
A4: Paso 1 | B4: x5 — x2 | C4: 0.6869 | D4: x5 → x2 | E4: {x2, x5} | F4: 0.6869
A5: Paso 2 | B5: x5 — x1 | C5: 0.4237 | D5: x5 → x1 | E5: {x2, x5, x1} | F5: 1.1106
A6: Paso 3 | B6: x5 — x9 | C6: 0.0069 | D6: x5 → x9 | E6: {x9, x2, x5, x1} | F6: 1.1175
A7: Paso 4 | B7: x9 — x6 | C7: 0.9998 | D7: x9 → x6 | E7: {x2, x6, x1, x9, x5} | F7: 2.1174
A8: Paso 5 | B8: x9 — x4 | C8: 0.686 | D8: x9 → x4 | E8: {x4, x2, x6, x1, x9, x5} | F8: 2.8034
A9: Paso 6 | B9: x9 — x3 | C9: 0.0058 | D9: x9 → x3 | E9: {x4, x2, x6, x1, x3, x9, x5} | F9: 2.8092
A11: PESO TOTAL MST (Prim) | F11: 2.8092

Sheet A-MST Resumen
A1: Dataset A — MST Resumen
A3: # | B3: Arista | C3: Peso IM | D3: Acumulado
A4: 1 | B4: x6 — x9 | C4: 0.9998 | D4: 0.9998
A5: 2 | B5: x2 — x5 | C5: 0.6869 | D5: 1.6867
A6: 3 | B6: x4 — x9 | C6: 0.686 | D6: 2.3728
A7: 4 | B7: x1 — x5 | C7: 0.4237 | D7: 2.7965
A8: 5 | B8: x5 — x9 | C8: 0.0069 | D8: 2.8034
A9: 6 | B9: x9 — x3 | C9: 0.0058 | D9: 2.8092
A11: PESO TOTAL MST | C11: 2.8092

Sheet _Data_B
A1: x1 | B1: x2 | C1: x5 | D1: x4 | E1: x6 | F1: x9 | G1: x3
A2: 1 | B2: 0 | C2: 2 | D2: 0 | E2: 1 | F2: 1 | G2: 1
A3: 0 | B3: 0 | C3: 0 | D3: 1 | E3: 1 | F3: 3 | G3: 0
A4: 0 | B4: 1 | C4: 1 | D4: 1 | E4: 0 | F4: 2 | G4: 1
A5: 0 | B5: 0 | C5: 0 | D5: 1 | E5: 0 | F5: 2 | G5: 1
A6: 0 | B6: 0 | C6: 0 | D6: 0 | E6: 0 | F6: 0 | G6: 1
A7: 0 | B7: 1 | C7: 1 | D7: 1 | E7: 1 | F7: 3 | G7: 1
A8: 0 | B8: 0 | C8: 0 | D8: 1 | E8: 1 | F8: 3 | G8: 1
A9: 0 | B9: 1 | C9: 1 | D9: 1 | E9: 0 | F9: 2 | G9: 1
A10: 0 | B10: 0 | C10: 0 | D10: 1 | E10: 0 | F10: 2 | G10: 1
A11: 0 | B11: 1 | C11: 1 | D11: 1 | E11: 1 | F11: 3 | G11: 1
A12: 0 | B12: 1 | C12: 1 | D12: 1 | E12: 1 | F12: 3 | G12: 1
A13: 1 | B13: 0 | C13: 2 | D13: 1 | E13: 0 | F13: 2 | G13: 1
... A503: 0 | B503: 0 | C503: 0 | D503: 1 | E503: 0 | F503: 2 | G503: 1

Sheet _Calc_B
A1: CÁLCULOS MI — Dataset B
A2: N = | B2: 502
A4: x1 — x2
A5: x1 | B5: x2 | C5: freq | D5: p(x1,x2) | E5: p(x1) | F5: p(x2) | G5: p(a)·p(b) | H5: ratio | I5: log₂(ratio) | J5: p·log₂(ratio)
A6: 0 | B6: 0 | C6: =COUNTIFS(_Data_B!A:A,0,_Data_B!B:B,0) | D6: =IF(C6=0,0,C6/502) | E6: =IF(C6=0,0,COUNTIF(_Data_B!A:A,0)/502) | F6: =IF(C6=0,0,COUNTIF(_Data_B!B:B,0)/502) | G6: =IF(D6=0,0,E6*F6) | H6: =IF(G6=0,0,D6/G6) | I6: =IF(H6<=0,0,LOG(H6,2)) | J6: =D6*I6
A7: 0 | B7: 1 | C7: =COUNTIFS(_Data_B!A:A,0,_Data_B!B:B,1) | D7: =IF(C7=0,0,C7/502) | E7: =IF(C7=0,0,COUNTIF(_Data_B!A:A,0)/502) | F7: =IF(C7=0,0,COUNTIF(_Data_B!B:B,1)/502) | G7: =IF(D7=0,0,E7*F7) | H7: =IF(G7=0,0,D7/G7) | I7: =IF(H7<=0,0,LOG(H7,2)) | J7: =D7*I7
A8: 1 | B8: 0 | C8: =COUNTIFS(_Data_B!A:A,1,_Data_B!B:B,0) | D8: =IF(C8=0,0,C8/502) | E8: =IF(C8=0,0,COUNTIF(_Data_B!A:A,1)/502) | F8: =IF(C8=0,0,COUNTIF(_Data_B!B:B,0)/502) | G8: =IF(D8=0,0,E8*F8) | H8: =IF(G8=0,0,D8/G8) | I8: =IF(H8<=0,0,LOG(H8,2)) | J8: =D8*I8
A9: 1 | B9: 1 | C9: =COUNTIFS(_Data_B!A:A,1,_Data_B!B:B,1) | D9: =IF(C9=0,0,C9/502) | E9: =IF(C9=0,0,COUNTIF(_Data_B!A:A,1)/502) | F9: =IF(C9=0,0,COUNTIF(_Data_B!B:B,1)/502) | G9: =IF(D9=0,0,E9*F9) | H9: =IF(G9=0,0,D9/G9) | I9: =IF(H9<=0,0,LOG(H9,2)) | J9: =D9*I9
A10: IM(x1,x2) = | J10: =SUM(J6:J9)
A13: x1 — x5
A14: x1 | B14: x5 | C14: freq | D14: p(x1,x5) | E14: p(x1) | F14: p(x5) | G14: p(a)·p(b) | H14: ratio | I14: log₂(ratio) | J14: p·log₂(ratio)
A15: 0 | B15: 0 | C15: =COUNTIFS(_Data_B!A:A,0,_Data_B!C:C,0) | D15: =IF(C15=0,0,C15/502) | E15: =IF(C15=0,0,COUNTIF(_Data_B!A:A,0)/502) | F15: =IF(C15=0,0,COUNTIF(_Data_B!C:C,0)/502) | G15: =IF(D15=0,0,E15*F15) | H15: =IF(G15=0,0,D15/G15) | I15: =IF(H15<=0,0,LOG(H15,2)) | J15: =D15*I15
A16: 0 | B16: 1 | C16: =COUNTIFS(_Data_B!A:A,0,_Data_B!C:C,1) | D16: =IF(C16=0,0,C16/502) | E16: =IF(C16=0,0,COUNTIF(_Data_B!A:A,0)/502) | F16: =IF(C16=0,0,COUNTIF(_Data_B!C:C,1)/502) | G16: =IF(D16=0,0,E16*F16) | H16: =IF(G16=0,0,D16/G16) | I16: =IF(H16<=0,0,LOG(H16,2)) | J16: =D16*I16
A17: 0 | B17: 2 | C17: =COUNTIFS(_Data_B!A:A,0,_Data_B!C:C,2) | D17: =IF(C17=0,0,C17/502) | E17: =IF(C17=0,0,COUNTIF(_Data_B!A:A,0)/502) | F17: =IF(C17=0,0,COUNTIF(_Data_B!C:C,2)/502) | G17: =IF(D17=0,0,E17*F17) | H17: =IF(G17=0,0,D17/G17) | I17: =IF(H17<=0,0,LOG(H17,2)) | J17: =D17*I17
A18: 1 | B18: 0 | C18: =COUNTIFS(_Data_B!A:A,1,_Data_B!C:C,0) | D18: =IF(C18=0,0,C18/502) | E18: =IF(C18=0,0,COUNTIF(_Data_B!A:A,1)/502) | F18: =IF(C18=0,0,COUNTIF(_Data_B!C:C,0)/502) | G18: =IF(D18=0,0,E18*F18) | H18: =IF(G18=0,0,D18/G18) | I18: =IF(H18<=0,0,LOG(H18,2)) | J18: =D18*I18
A19: 1 | B19: 1 | C19: =COUNTIFS(_Data_B!A:A,1,_Data_B!C:C,1) | D19: =IF(C19=0,0,C19/502) | E19: =IF(C19=0,0,COUNTIF(_Data_B!A:A,1)/502) | F19: =IF(C19=0,0,COUNTIF(_Data_B!C:C,1)/502) | G19: =IF(D19=0,0,E19*F19) | H19: =IF(G19=0,0,D19/G19) | I19: =IF(H19<=0,0,LOG(H19,2)) | J19: =D19*I19
A20: 1 | B20: 2 | C20: =COUNTIFS(_Data_B!A:A,1,_Data_B!C:C,2) | D20: =IF(C20=0,0,C20/502) | E20: =IF(C20=0,0,COUNTIF(_Data_B!A:A,1)/502) | F20: =IF(C20=0,0,COUNTIF(_Data_B!C:C,2)/502) | G20: =IF(D20=0,0,E20*F20) | H20: =IF(G20=0,0,D20/G20) | I20: =IF(H20<=0,0,LOG(H20,2)) | J20: =D20*I20
A21: IM(x1,x5) = | J21: =SUM(J15:J20)
A24: x1 — x4
A25: x1 | B25: x4 | C25: freq | D25: p(x1,x4) | E25: p(x1) | F25: p(x4) | G25: p(a)·p(b) | H25: ratio | I25: log₂(ratio) | J25: p·log₂(ratio)
A26: 0 | B26: 0 | C26: =COUNTIFS(_Data_B!A:A,0,_Data_B!D:D,0) | D26: =IF(C26=0,0,C26/502) | E26: =IF(C26=0,0,COUNTIF(_Data_B!A:A,0)/502) | F26: =IF(C26=0,0,COUNTIF(_Data_B!D:D,0)/502) | G26: =IF(D26=0,0,E26*F26) | H26: =IF(G26=0,0,D26/G26) | I26: =IF(H26<=0,0,LOG(H26,2)) | J26: =D26*I26
A27: 0 | B27: 1 | C27: =COUNTIFS(_Data_B!A:A,0,_Data_B!D:D,1) | D27: =IF(C27=0,0,C27/502) | E27: =IF(C27=0,0,COUNTIF(_Data_B!A:A,0)/502) | F27: =IF(C27=0,0,COUNTIF(_Data_B!D:D,1)/502) | G27: =IF(D27=0,0,E27*F27) | H27: =IF(G27=0,0,D27/G27) | I27: =IF(H27<=0,0,LOG(H27,2)) | J27: =D27*I27
A28: 1 | B28: 0 | C28: =COUNTIFS(_Data_B!A:A,1,_Data_B!D:D,0) | D28: =IF(C28=0,0,C28/502) | E28: =IF(C28=0,0,COUNTIF(_Data_B!A:A,1)/502) | F28: =IF(C28=0,0,COUNTIF(_Data_B!D:D,0)/502) | G28: =IF(D28=0,0,E28*F28) | H28: =IF(G28=0,0,D28/G28) | I28: =IF(H28<=0,0,LOG(H28,2)) | J28: =D28*I28
A29: 1 | B29: 1 | C29: =COUNTIFS(_Data_B!A:A,1,_Data_B!D:D,1) | D29: =IF(C29=0,0,C29/502) | E29: =IF(C29=0,0,COUNTIF(_Data_B!A:A,1)/502) | F29: =IF(C29=0,0,COUNTIF(_Data_B!D:D,1)/502) | G29: =IF(D29=0,0,E29*F29) | H29: =IF(G29=0,0,D29/G29) | I29: =IF(H29<=0,0,LOG(H29,2)) | J29: =D29*I29
A30: IM(x1,x4) = | J30: =SUM(J26:J29)
A33: x1 — x6
A34: x1 | B34: x6 | C34: freq | D34: p(x1,x6) | E34: p(x1) | F34: p(x6) | G34: p(a)·p(b) | H34: ratio | I34: log₂(ratio) | J34: p·log₂(ratio)
A35: 0 | B35: 0 | C35: =COUNTIFS(_Data_B!A:A,0,_Data_B!E:E,0) | D35: =IF(C35=0,0,C35/502) | E35: =IF(C35=0,0,COUNTIF(_Data_B!A:A,0)/502) | F35: =IF(C35=0,0,COUNTIF(_Data_B!E:E,0)/502) | G35: =IF(D35=0,0,E35*F35) | H35: =IF(G35=0,0,D35/G35) | I35: =IF(H35<=0,0,LOG(H35,2)) | J35: =D35*I35
A36: 0 | B36: 1 | C36: =COUNTIFS(_Data_B!A:A,0,_Data_B!E:E,1) | D36: =IF(C36=0,0,C36/502) | E36: =IF(C36=0,0,COUNTIF(_Data_B!A:A,0)/502) | F36: =IF(C36=0,0,COUNTIF(_Data_B!E:E,1)/502) | G36: =IF(D36=0,0,E36*F36) | H36: =IF(G36=0,0,D36/G36) | I36: =IF(H36<=0,0,LOG(H36,2)) | J36: =D36*I36
A37: 1 | B37: 0 | C37: =COUNTIFS(_Data_B!A:A,1,_Data_B!E:E,0) | D37: =IF(C37=0,0,C37/502) | E37: =IF(C37=0,0,COUNTIF(_Data_B!A:A,1)/502) | F37: =IF(C37=0,0,COUNTIF(_Data_B!E:E,0)/502) | G37: =IF(D37=0,0,E37*F37) | H37: =IF(G37=0,0,D37/G37) | I37: =IF(H37<=0,0,LOG(H37,2)) | J37: =D37*I37
A38: 1 | B38: 1 | C38: =COUNTIFS(_Data_B!A:A,1,_Data_B!E:E,1) | D38: =IF(C38=0,0,C38/502) | E38: =IF(C38=0,0,COUNTIF(_Data_B!A:A,1)/502) | F38: =IF(C38=0,0,COUNTIF(_Data_B!E:E,1)/502) | G38: =IF(D38=0,0,E38*F38) | H38: =IF(G38=0,0,D38/G38) | I38: =IF(H38<=0,0,LOG(H38,2)) | J38: =D38*I38
A39: IM(x1,x6) = | J39: =SUM(J35:J38)
A42: x1 — x9
A43: x1 | B43: x9 | C43: freq | D43: p(x1,x9) | E43: p(x1) | F43: p(x9) | G43: p(a)·p(b) | H43: ratio | I43: log₂(ratio) | J43: p·log₂(ratio)
A44: 0 | B44: 0 | C44: =COUNTIFS(_Data_B!A:A,0,_Data_B!F:F,0) | D44: =IF(C44=0,0,C44/502) | E44: =IF(C44=0,0,COUNTIF(_Data_B!A:A,0)/502) | F44: =IF(C44=0,0,COUNTIF(_Data_B!F:F,0)/502) | G44: =IF(D44=0,0,E44*F44) | H44: =IF(G44=0,0,D44/G44) | I44: =IF(H44<=0,0,LOG(H44,2)) | J44: =D44*I44
A45: 0 | B45: 1 | C45: =COUNTIFS(_Data_B!A:A,0,_Data_B!F:F,1) | D45: =IF(C45=0,0,C45/502) | E45: =IF(C45=0,0,COUNTIF(_Data_B!A:A,0)/502) | F45: =IF(C45=0,0,COUNTIF(_Data_B!F:F,1)/502) | G45: =IF(D45=0,0,E45*F45) | H45: =IF(G45=0,0,D45/G45) | I45: =IF(H45<=0,0,LOG(H45,2)) | J45: =D45*I45
A46: 0 | B46: 2 | C46: =COUNTIFS(_Data_B!A:A,0,_Data_B!F:F,2) | D46: =IF(C46=0,0,C46/502) | E46: =IF(C46=0,0,COUNTIF(_Data_B!A:A,0)/502) | F46: =IF(C46=0,0,COUNTIF(_Data_B!F:F,2)/502) | G46: =IF(D46=0,0,E46*F46) | H46: =IF(G46=0,0,D46/G46) | I46: =IF(H46<=0,0,LOG(H46,2)) | J46: =D46*I46
A47: 0 | B47: 3 | C47: =COUNTIFS(_Data_B!A:A,0,_Data_B!F:F,3) | D47: =IF(C47=0,0,C47/502) | E47: =IF(C47=0,0,COUNTIF(_Data_B!A:A,0)/502) | F47: =IF(C47=0,0,COUNTIF(_Data_B!F:F,3)/502) | G47: =IF(D47=0,0,E47*F47) | H47: =IF(G47=0,0,D47/G47) | I47: =IF(H47<=0,0,LOG(H47,2)) | J47: =D47*I47
A48: 1 | B48: 0 | C48: =COUNTIFS(_Data_B!A:A,1,_Data_B!F:F,0) | D48: =IF(C48=0,0,C48/502) | E48: =IF(C48=0,0,COUNTIF(_Data_B!A:A,1)/502) | F48: =IF(C48=0,0,COUNTIF(_Data_B!F:F,0)/502) | G48: =IF(D48=0,0,E48*F48) | H48: =IF(G48=0,0,D48/G48) | I48: =IF(H48<=0,0,LOG(H48,2)) | J48: =D48*I48
A49: 1 | B49: 1 | C49: =COUNTIFS(_Data_B!A:A,1,_Data_B!F:F,1) | D49: =IF(C49=0,0,C49/502) | E49: =IF(C49=0,0,COUNTIF(_Data_B!A:A,1)/502) | F49: =IF(C49=0,0,COUNTIF(_Data_B!F:F,1)/502) | G49: =IF(D49=0,0,E49*F49) | H49: =IF(G49=0,0,D49/G49) | I49: =IF(H49<=0,0,LOG(H49,2)) | J49: =D49*I49
...

Sheet B-Entropias
A1: Dataset B — Entropía de Shannon
A2: Registros: 502
A4: H(x1)
A5: Valor (x) | B5: Frecuencia | C5: p(x) | D5: -log₂(p(x)) | E5: -p(x)·log₂(p(x))
A6: 0 | B6: =COUNTIF(_Data_B!A:A,0) | C6: =B6/502 | D6: =IF(C6=0,0,-LOG(C6,2)) | E6: =IF(C6=0,0,-C6*LOG(C6,2))
A7: 1 | B7: =COUNTIF(_Data_B!A:A,1) | C7: =B7/502 | D7: =IF(C7=0,0,-LOG(C7,2)) | E7: =IF(C7=0,0,-C7*LOG(C7,2))
A8: Total | B8: =SUM(B6:B7) | C8: 1 | D8: H(x1) = | E8: =SUM(E6:E7)
A11: H(x2)
A12: Valor (x) | B12: Frecuencia | C12: p(x) | D12: -log₂(p(x)) | E12: -p(x)·log₂(p(x))
A13: 0 | B13: =COUNTIF(_Data_B!B:B,0) | C13: =B13/502 | D13: =IF(C13=0,0,-LOG(C13,2)) | E13: =IF(C13=0,0,-C13*LOG(C13,2))
A14: 1 | B14: =COUNTIF(_Data_B!B:B,1) | C14: =B14/502 | D14: =IF(C14=0,0,-LOG(C14,2)) | E14: =IF(C14=0,0,-C14*LOG(C14,2))
A15: Total | B15: =SUM(B13:B14) | C15: 1 | D15: H(x2) = | E15: =SUM(E13:E14)
A18: H(x5)
A19: Valor (x) | B19: Frecuencia | C19: p(x) | D19: -log₂(p(x)) | E19: -p(x)·log₂(p(x))
A20: 0 | B20: =COUNTIF(_Data_B!C:C,0) | C20: =B20/502 | D20: =IF(C20=0,0,-LOG(C20,2)) | E20: =IF(C20=0,0,-C20*LOG(C20,2))
A21: 1 | B21: =COUNTIF(_Data_B!C:C,1) | C21: =B21/502 | D21: =IF(C21=0,0,-LOG(C21,2)) | E21: =IF(C21=0,0,-C21*LOG(C21,2))
A22: 2 | B22: =COUNTIF(_Data_B!C:C,2) | C22: =B22/502 | D22: =IF(C22=0,0,-LOG(C22,2)) | E22: =IF(C22=0,0,-C22*LOG(C22,2))
A23: Total | B23: =SUM(B20:B22) | C23: 1 | D23: H(x5) = | E23: =SUM(E20:E22)
A26: H(x4)
A27: Valor (x) | B27: Frecuencia | C27: p(x) | D27: -log₂(p(x)) | E27: -p(x)·log₂(p(x))
A28: 0 | B28: =COUNTIF(_Data_B!D:D,0) | C28: =B28/502 | D28: =IF(C28=0,0,-LOG(C28,2)) | E28: =IF(C28=0,0,-C28*LOG(C28,2))
A29: 1 | B29: =COUNTIF(_Data_B!D:D,1) | C29: =B29/502 | D29: =IF(C29=0,0,-LOG(C29,2)) | E29: =IF(C29=0,0,-C29*LOG(C29,2))
A30: Total | B30: =SUM(B28:B29) | C30: 1 | D30: H(x4) = | E30: =SUM(E28:E29)
A33: H(x6)
A34: Valor (x) | B34: Frecuencia | C34: p(x) | D34: -log₂(p(x)) | E34: -p(x)·log₂(p(x))
A35: 0 | B35: =COUNTIF(_Data_B!E:E,0) | C35: =B35/502 | D35: =IF(C35=0,0,-LOG(C35,2)) | E35: =IF(C35=0,0,-C35*LOG(C35,2))
A36: 1 | B36: =COUNTIF(_Data_B!E:E,1) | C36: =B36/502 | D36: =IF(C36=0,0,-LOG(C36,2)) | E36: =IF(C36=0,0,-C36*LOG(C36,2))
A37: Total | B37: =SUM(B35:B36) | C37: 1 | D37: H(x6) = | E37: =SUM(E35:E36)
A40: H(x9)
A41: Valor (x) | B41: Frecuencia | C41: p(x) | D41: -log₂(p(x)) | E41: -p(x)·log₂(p(x))
A42: 0 | B42: =COUNTIF(_Data_B!F:F,0) | C42: =B42/502 | D42: =IF(C42=0,0,-LOG(C42,2)) | E42: =IF(C42=0,0,-C42*LOG(C42,2))
A43: 1 | B43: =COUNTIF(_Data_B!F:F,1) | C43: =B43/502 | D43: =IF(C43=0,0,-LOG(C43,2)) | E43: =IF(C43=0,0,-C43*LOG(C43,2))
A44: 2 | B44: =COUNTIF(_Data_B!F:F,2) | C44: =B44/502 | D44: =IF(C44=0,0,-LOG(C44,2)) | E44: =IF(C44=0,0,-C44*LOG(C44,2))
A45: 3 | B45: =COUNTIF(_Data_B!F:F,3) | C45: =B45/502 | D45: =IF(C45=0,0,-LOG(C45,2)) | E45: =IF(C45=0,0,-C45*LOG(C45,2))
A46: Total | B46: =SUM(B42:B45) | C46: 1 | D46: H(x9) = | E46: =SUM(E42:E45)
A49: H(x3)
A50: Valor (x) | B50: Frecuencia | C50: p(x) | D50: -log₂(p(x)) | E50: -p(x)·log₂(p(x))
A51: 0 | B51: =COUNTIF(_Data_B!G:G,0) | C51: =B51/502 | D51: =IF(C51=0,0,-LOG(C51,2)) | E51: =IF(C51=0,0,-C51*LOG(C51,2))
A52: 1 | B52: =COUNTIF(_Data_B!G:G,1) | C52: =B52/502 | D52: =IF(C52=0,0,-LOG(C52,2)) | E52: =IF(C52=0,0,-C52*LOG(C52,2))
A53: Total | B53: =SUM(B51:B52) | C53: 1 | D53: H(x3) = | E53: =SUM(E51:E52)

Sheet B-Matriz MI
A1: Dataset B — Matriz de Información Mutua
A3: IM(X,Y) | B3: x1 | C3: x2 | D3: x5 | E3: x4 | F3: x6 | G3: x9 | H3: x3
A4: x1 | B4: 0 | C4: =_Calc_B!J10 | D4: =_Calc_B!J21 | E4: =_Calc_B!J30 | F4: =_Calc_B!J39 | G4: =_Calc_B!J52 | H4: =_Calc_B!J61
A5: x2 | B5: =_Calc_B!J10 | C5: 0 | D5: =_Calc_B!J72 | E5: =_Calc_B!J81 | F5: =_Calc_B!J90 | G5: =_Calc_B!J103 | H5: =_Calc_B!J112
A6: x5 | B6: =_Calc_B!J21 | C6: =_Calc_B!J72 | D6: 0 | E6: =_Calc_B!J123 | F6: =_Calc_B!J134 | G6: =_Calc_B!J151 | H6: =_Calc_B!J162
A7: x4 | B7: =_Calc_B!J30 | C7: =_Calc_B!J81 | D7: =_Calc_B!J123 | E7: 0 | F7: =_Calc_B!J171 | G7: =_Calc_B!J184 | H7: =_Calc_B!J193
A8: x6 | B8: =_Calc_B!J39 | C8: =_Calc_B!J90 | D8: =_Calc_B!J134 | E8: =_Calc_B!J171 | F8: 0 | G8: =_Calc_B!J206 | H8: =_Calc_B!J215
A9: x9 | B9: =_Calc_B!J52 | C9: =_Calc_B!J103 | D9: =_Calc_B!J151 | E9: =_Calc_B!J184 | F9: =_Calc_B!J206 | G9: 0 | H9: =_Calc_B!J228
A10: x3 | B10: =_Calc_B!J61 | C10: =_Calc_B!J112 | D10: =_Calc_B!J162 | E10: =_Calc_B!J193 | F10: =_Calc_B!J215 | G10: =_Calc_B!J228 | H10: 0

Sheet B-MI Detalle (x1-x5)
A1: Dataset B — Cálculo Detallado IM(x1,x5)
A3: Tabla de Probabilidades Conjuntas
A5: x1 | B5: x5 | C5: Frecuencia | D5: p(x1,x5) | E5: p(x1) | F5: p(x5) | G5: p/(px·py) | H5: log₂(ratio) | I5: p·log₂(ratio)
A6: 0 | B6: 0 | C6: =COUNTIFS(_Data_B!A:A,0,_Data_B!C:C,0) | D6: =C6/502 | E6: =IF(D6=0,0,COUNTIF(_Data_B!A:A,0)/502) | F6: =IF(D6=0,0,COUNTIF(_Data_B!C:C,0)/502) | G6: =IF(D6=0,0,D6/(E6*F6)) | H6: =IF(G6<=0,0,LOG(G6,2)) | I6: =D6*H6
A7: 0 | B7: 1 | C7: =COUNTIFS(_Data_B!A:A,0,_Data_B!C:C,1) | D7: =C7/502 | E7: =IF(D7=0,0,COUNTIF(_Data_B!A:A,0)/502) | F7: =IF(D7=0,0,COUNTIF(_Data_B!C:C,1)/502) | G7: =IF(D7=0,0,D7/(E7*F7)) | H7: =IF(G7<=0,0,LOG(G7,2)) | I7: =D7*H7
A8: 0 | B8: 2 | C8: =COUNTIFS(_Data_B!A:A,0,_Data_B!C:C,2) | D8: =C8/502 | E8: =IF(D8=0,0,COUNTIF(_Data_B!A:A,0)/502) | F8: =IF(D8=0,0,COUNTIF(_Data_B!C:C,2)/502) | G8: =IF(D8=0,0,D8/(E8*F8)) | H8: =IF(G8<=0,0,LOG(G8,2)) | I8: =D8*H8
A9: 1 | B9: 0 | C9: =COUNTIFS(_Data_B!A:A,1,_Data_B!C:C,0) | D9: =C9/502 | E9: =IF(D9=0,0,COUNTIF(_Data_B!A:A,1)/502) | F9: =IF(D9=0,0,COUNTIF(_Data_B!C:C,0)/502) | G9: =IF(D9=0,0,D9/(E9*F9)) | H9: =IF(G9<=0,0,LOG(G9,2)) | I9: =D9*H9
A10: 1 | B10: 1 | C10: =COUNTIFS(_Data_B!A:A,1,_Data_B!C:C,1) | D10: =C10/502 | E10: =IF(D10=0,0,COUNTIF(_Data_B!A:A,1)/502) | F10: =IF(D10=0,0,COUNTIF(_Data_B!C:C,1)/502) | G10: =IF(D10=0,0,D10/(E10*F10)) | H10: =IF(G10<=0,0,LOG(G10,2)) | I10: =D10*H10
A11: 1 | B11: 2 | C11: =COUNTIFS(_Data_B!A:A,1,_Data_B!C:C,2) | D11: =C11/502 | E11: =IF(D11=0,0,COUNTIF(_Data_B!A:A,1)/502) | F11: =IF(D11=0,0,COUNTIF(_Data_B!C:C,2)/502) | G11: =IF(D11=0,0,D11/(E11*F11)) | H11: =IF(G11<=0,0,LOG(G11,2)) | I11: =D11*H11
E12: IM(x1,x5) = Σ | I12: =SUM(I6:I11)

Sheet B-Kruskal
A1: Dataset B — Algoritmo de Kruskal (MST)
F2: comp(x1) | G2: comp(x2) | H2: comp(x5) | I2: comp(x4) | J2: comp(x6) | K2: comp(x9) | L2: comp(x3)
A3: # | B3: Arista | C3: Peso IM | D3: Decisión | E3: Justificación | F3: x1 | G3: x2 | H3: x5 | I3: x4 | J3: x6 | K3: x9 | L3: x3 | M3: comp(u) | N3: comp(v) | O3: Acum
A4: 1 | B4: x6 — x9 | C4: ='B-Matriz MI'!G9 | D4: =IF(M4=N4,"Rechazado","Aceptado") | E4: =IF(D4="Aceptado","","Ciclo: x6 y x9 ya conectados") | F4: 1 | G4: 2 | H4: 3 | I4: 4 | J4: 5 | K4: 6 | L4: 7 | M4: =J4 | N4: =K4 | O4: =IF(D4="Aceptado",C4,0)
A5: 2 | B5: x4 — x9 | C5: ='B-Matriz MI'!G8 | D5: =IF(M5=N5,"Rechazado","Aceptado") | E5: =IF(D5="Aceptado","","Ciclo: x4 y x9 ya conectados") | F5: =IF(D4="Aceptado",IF(F4=N4,M4,F4),F4) | G5: =IF(D4="Aceptado",IF(G4=N4,M4,G4),G4) | H5: =IF(D4="Aceptado",IF(H4=N4,M4,H4),H4) | I5: =IF(D4="Aceptado",IF(I4=N4,M4,I4),I4) | J5: =IF(D4="Aceptado",IF(J4=N4,M4,J4),J4) | K5: =IF(D4="Aceptado",IF(K4=N4,M4,K4),K4) | L5: =IF(D4="Aceptado",IF(L4=N4,M4,L4),L4) | M5: =I5 | N5: =K5 | O5: =IF(D5="Aceptado",O4+C5,O4)
A6: 3 | B6: x2 — x5 | C6: ='B-Matriz MI'!D6 | D6: =IF(M6=N6,"Rechazado","Aceptado") | E6: =IF(D6="Aceptado","","Ciclo: x2 y x5 ya conectados") | F6: =IF(D5="Aceptado",IF(F5=N5,M5,F5),F5) | G6: =IF(D5="Aceptado",IF(G5=N5,M5,G5),G5) | H6: =IF(D5="Aceptado",IF(H5=N5,M5,H5),H5) | I6: =IF(D5="Aceptado",IF(I5=N5,M5,I5),I5) | J6: =IF(D5="Aceptado",IF(J5=N5,M5,J5),J5) | K6: =IF(D5="Aceptado",IF(K5=N5,M5,K5),K5) | L6: =IF(D5="Aceptado",IF(L5=N5,M5,L5),L5) | M6: =G6 | N6: =H6 | O6: =IF(D6="Aceptado",O5+C6,O5)
A7: 4 | B7: x1 — x5 | C7: ='B-Matriz MI'!D5 | D7: =IF(M7=N7,"Rechazado","Aceptado") | E7: =IF(D7="Aceptado","","Ciclo: x1 y x5 ya conectados") | F7: =IF(D6="Aceptado",IF(F6=N6,M6,F6),F6) | G7: =IF(D6="Aceptado",IF(G6=N6,M6,G6),G6) | H7: =IF(D6="Aceptado",IF(H6=N6,M6,H6),H6) | I7: =IF(D6="Aceptado",IF(I6=N6,M6,I6),I6) | J7: =IF(D6="Aceptado",IF(J6=N6,M6,J6),J6) | K7: =IF(D6="Aceptado",IF(K6=N6,M6,K6),K6) | L7: =IF(D6="Aceptado",IF(L6=N6,M6,L6),L6) | M7: =F7 | N7: =H7 | O7: =IF(D7="Aceptado",O6+C7,O6)
A8: 5 | B8: x5 — x9 | C8: ='B-Matriz MI'!G7 | D8: =IF(M8=N8,"Rechazado","Aceptado") | E8: =IF(D8="Aceptado","","Ciclo: x5 y x9 ya conectados") | F8: =IF(D7="Aceptado",IF(F7=N7,M7,F7),F7) | G8: =IF(D7="Aceptado",IF(G7=N7,M7,G7),G7) | H8: =IF(D7="Aceptado",IF(H7=N7,M7,H7),H7) | I8: =IF(D7="Aceptado",IF(I7=N7,M7,I7),I7) | J8: =IF(D7="Aceptado",IF(J7=N7,M7,J7),J7) | K8: =IF(D7="Aceptado",IF(K7=N7,M7,K7),K7) | L8: =IF(D7="Aceptado",IF(L7=N7,M7,L7),L7) | M8: =H8 | N8: =K8 | O8: =IF(D8="Aceptado",O7+C8,O7)
A9: 6 | B9: x5 — x6 | C9: ='B-Matriz MI'!F7 | D9: =IF(M9=N9,"Rechazado","Aceptado") | E9: =IF(D9="Aceptado","","Ciclo: x5 y x6 ya conectados") | F9: =IF(D8="Aceptado",IF(F8=N8,M8,F8),F8) | G9: =IF(D8="Aceptado",IF(G8=N8,M8,G8),G8) | H9: =IF(D8="Aceptado",IF(H8=N8,M8,H8),H8) | I9: =IF(D8="Aceptado",IF(I8=N8,M8,I8),I8) | J9: =IF(D8="Aceptado",IF(J8=N8,M8,J8),J8) | K9: =IF(D8="Aceptado",IF(K8=N8,M8,K8),K8) | L9: =IF(D8="Aceptado",IF(L8=N8,M8,L8),L8) | M9: =H9 | N9: =J9 | O9: =IF(D9="Aceptado",O8+C9,O8)
A10: 7 | B10: x1 — x9 | C10: ='B-Matriz MI'!G5 | D10: =IF(M10=N10,"Rechazado","Aceptado") | E10: =IF(D10="Aceptado","","Ciclo: x1 y x9 ya conectados") | F10: =IF(D9="Aceptado",IF(F9=N9,M9,F9),F9) | G10: =IF(D9="Aceptado",IF(G9=N9,M9,G9),G9) | H10: =IF(D9="Aceptado",IF(H9=N9,M9,H9),H9) | I10: =IF(D9="Aceptado",IF(I9=N9,M9,I9),I9) | J10: =IF(D9="Aceptado",IF(J9=N9,M9,J9),J9) | K10: =IF(D9="Aceptado",IF(K9=N9,M9,K9),K9) | L10: =IF(D9="Aceptado",IF(L9=N9,M9,L9),L9) | M10: =F10 | N10: =K10 | O10: =IF(D10="Aceptado",O9+C10,O9)
A11: 8 | B11: x1 — x6 | C11: ='B-Matriz MI'!F5 | D11: =IF(M11=N11,"Rechazado","Aceptado") | E11: =IF(D11="Aceptado","","Ciclo: x1 y x6 ya conectados") | F11: =IF(D10="Aceptado",IF(F10=N10,M10,F10),F10) | G11: =IF(D10="Aceptado",IF(G10=N10,M10,G10),G10) | H11: =IF(D10="Aceptado",IF(H10=N10,M10,H10),H10) | I11: =IF(D10="Aceptado",IF(I10=N10,M10,I10),I10) | J11: =IF(D10="Aceptado",IF(J10=N10,M10,J10),J10) | K11: =IF(D10="Aceptado",IF(K10=N10,M10,K10),K10) | L11: =IF(D10="Aceptado",IF(L10=N10,M10,L10),L10) | M11: =F11 | N11: =J11 | O11: =IF(D11="Aceptado",O10+C11,O10)
A12: 9 | B12: x5 — x4 | C12: ='B-Matriz MI'!E7 | D12: =IF(M12=N12,"Rechazado","Aceptado") | E12: =IF(D12="Aceptado","","Ciclo: x5 y x4 ya conectados") | F12: =IF(D11="Aceptado",IF(F11=N11,M11,F11),F11) | G12: =IF(D11="Aceptado",IF(G11=N11,M11,G11),G11) | H12: =IF(D11="Aceptado",IF(H11=N11,M11,H11),H11) | I12: =IF(D11="Aceptado",IF(I11=N11,M11,I11),I11) | J12: =IF(D11="Aceptado",IF(J11=N11,M11,J11),J11) | K12: =IF(D11="Aceptado",IF(K11=N11,M11,K11),K11) | L12: =IF(D11="Aceptado",IF(L11=N11,M11,L11),L11) | M12: =H12 | N12: =I12 | O12: =IF(D12="Aceptado",O11+C12,O11)
A13: 10 | B13: x2 — x9 | C13: ='B-Matriz MI'!G6 | D13: =IF(M13=N13,"Rechazado","Aceptado") | E13: =IF(D13="Aceptado","","Ciclo: x2 y x9 ya conectados") | F13: =IF(D12="Aceptado",IF(F12=N12,M12,F12),F12) | G13: =IF(D12="Aceptado",IF(G12=N12,M12,G12),G12) | H13: =IF(D12="Aceptado",IF(H12=N12,M12,H12),H12) | I13: =IF(D12="Aceptado",IF(I12=N12,M12,I12),I12) | J13: =IF(D12="Aceptado",IF(J12=N12,M12,J12),J12) | K13: =IF(D12="Aceptado",IF(K12=N12,M12,K12),K12) | L13: =IF(D12="Aceptado",IF(L12=N12,M12,L12),L12) | M13: =G13 | N13: =K13 | O13: =IF(D13="Aceptado",O12+C13,O12)
A14: 11 | B14: x2 — x6 | C14: ='B-Matriz MI'!F6 | D14: =IF(M14=N14,"Rechazado","Aceptado") | E14: =IF(D14="Aceptado","","Ciclo: x2 y x6 ya conectados") | F14: =IF(D13="Aceptado",IF(F13=N13,M13,F13),F13) | G14: =IF(D13="Aceptado",IF(G13=N13,M13,G13),G13) | H14: =IF(D13="Aceptado",IF(H13=N13,M13,H13),H13) | I14: =IF(D13="Aceptado",IF(I13=N13,M13,I13),I13) | J14: =IF(D13="Aceptado",IF(J13=N13,M13,J13),J13) | K14: =IF(D13="Aceptado",IF(K13=N13,M13,K13),K13) | L14: =IF(D13="Aceptado",IF(L13=N13,M13,L13),L13) | M14: =G14 | N14: =J14 | O14: =IF(D14="Aceptado",O13+C14,O13)
A15: 12 | B15: x1 — x2 | C15: ='B-Matriz MI'!C5 | D15: =IF(M15=N15,"Rechazado","Aceptado") | E15: =IF(D15="Aceptado","","Ciclo: x1 y x2 ya conectados") | F15: =IF(D14="Aceptado",IF(F14=N14,M14,F14),F14) | G15: =IF(D14="Aceptado",IF(G14=N14,M14,G14),G14) | H15: =IF(D14="Aceptado",IF(H14=N14,M14,H14),H14) | I15: =IF(D14="Aceptado",IF(I14=N14,M14,I14),I14) | J15: =IF(D14="Aceptado",IF(J14=N14,M14,J14),J14) | K15: =IF(D14="Aceptado",IF(K14=N14,M14,K14),K14) | L15: =IF(D14="Aceptado",IF(L14=N14,M14,L14),L14) | M15: =F15 | N15: =G15 | O15: =IF(D15="Aceptado",O14+C15,O14)
A16: 13 | B16: x1 — x3 | C16: ='B-Matriz MI'!H5 | D16: =IF(M16=N16,"Rechazado","Aceptado") | E16: =IF(D16="Aceptado","","Ciclo: x1 y x3 ya conectados") | F16: =IF(D15="Aceptado",IF(F15=N15,M15,F15),F15) | G16: =IF(D15="Aceptado",IF(G15=N15,M15,G15),G15) | H16: =IF(D15="Aceptado",IF(H15=N15,M15,H15),H15) | I16: =IF(D15="Aceptado",IF(I15=N15,M15,I15),I15) | J16: =IF(D15="Aceptado",IF(J15=N15,M15,J15),J15) | K16: =IF(D15="Aceptado",IF(K15=N15,M15,K15),K15) | L16: =IF(D15="Aceptado",IF(L15=N15,M15,L15),L15) | M16: =F16 | N16: =L16 | O16: =IF(D16="Aceptado",O15+C16,O15)
A17: 14 | B17: x2 — x4 | C17: ='B-Matriz MI'!E6 | D17: =IF(M17=N17,"Rechazado","Aceptado") | E17: =IF(D17="Aceptado","","Ciclo: x2 y x4 ya conectados") | F17: =IF(D16="Aceptado",IF(F16=N16,M16,F16),F16) | G17: =IF(D16="Aceptado",IF(G16=N16,M16,G16),G16) | H17: =IF(D16="Aceptado",IF(H16=N16,M16,H16),H16) | I17: =IF(D16="Aceptado",IF(I16=N16,M16,I16),I16) | J17: =IF(D16="Aceptado",IF(J16=N16,M16,J16),J16) | K17: =IF(D16="Aceptado",IF(K16=N16,M16,K16),K16) | L17: =IF(D16="Aceptado",IF(L16=N16,M16,L16),L16) | M17: =G17 | N17: =I17 | O17: =IF(D17="Aceptado",O16+C17,O16)
A18: 15 | B18: x2 — x3 | C18: ='B-Matriz MI'!H6 | D18: =IF(M18=N18,"Rechazado","Aceptado") | E18: =IF(D18="Aceptado","","Ciclo: x2 y x3 ya conectados") | F18: =IF(D17="Aceptado",IF(F17=N17,M17,F17),F17) | G18: =IF(D17="Aceptado",IF(G17=N17,M17,G17),G17) | H18: =IF(D17="Aceptado",IF(H17=N17,M17,H17),H17) | I18: =IF(D17="Aceptado",IF(I17=N17,M17,I17),I17) | J18: =IF(D17="Aceptado",IF(J17=N17,M17,J17),J17) | K18: =IF(D17="Aceptado",IF(K17=N17,M17,K17),K17) | L18: =IF(D17="Aceptado",IF(L17=N17,M17,L17),L17) | M18: =G18 | N18: =L18 | O18: =IF(D18="Aceptado",O17+C18,O17)
A19: 16 | B19: x5 — x3 | C19: ='B-Matriz MI'!H7 | D19: =IF(M19=N19,"Rechazado","Aceptado") | E19: =IF(D19="Aceptado","","Ciclo: x5 y x3 ya conectados") | F19: =IF(D18="Aceptado",IF(F18=N18,M18,F18),F18) | G19: =IF(D18="Aceptado",IF(G18=N18,M18,G18),G18) | H19: =IF(D18="Aceptado",IF(H18=N18,M18,H18),H18) | I19: =IF(D18="Aceptado",IF(I18=N18,M18,I18),I18) | J19: =IF(D18="Aceptado",IF(J18=N18,M18,J18),J18) | K19: =IF(D18="Aceptado",IF(K18=N18,M18,K18),K18) | L19: =IF(D18="Aceptado",IF(L18=N18,M18,L18),L18) | M19: =H19 | N19: =L19 | O19: =IF(D19="Aceptado",O18+C19,O18)
A20: 17 | B20: x4 — x6 | C20: ='B-Matriz MI'!F8 | D20: =IF(M20=N20,"Rechazado","Aceptado") | E20: =IF(D20="Aceptado","","Ciclo: x4 y x6 ya conectados") | F20: =IF(D19="Aceptado",IF(F19=N19,M19,F19),F19) | G20: =IF(D19="Aceptado",IF(G19=N19,M19,G19),G19) | H20: =IF(D19="Aceptado",IF(H19=N19,M19,H19),H19) | I20: =IF(D19="Aceptado",IF(I19=N19,M19,I19),I19) | J20: =IF(D19="Aceptado",IF(J19=N19,M19,J19),J19) | K20: =IF(D19="Aceptado",IF(K19=N19,M19,K19),K19) | L20: =IF(D19="Aceptado",IF(L19=N19,M19,L19),L19) | M20: =I20 | N20: =J20 | O20: =IF(D20="Aceptado",O19+C20,O19)
A21: 18 | B21: x9 — x3 | C21: ='B-Matriz MI'!H10 | D21: =IF(M21=N21,"Rechazado","Aceptado") | E21: =IF(D21="Aceptado","","Ciclo: x9 y x3 ya conectados") | F21: =IF(D20="Aceptado",IF(F20=N20,M20,F20),F20) | G21: =IF(D20="Aceptado",IF(G20=N20,M20,G20),G20) | H21: =IF(D20="Aceptado",IF(H20=N20,M20,H20),H20) | I21: =IF(D20="Aceptado",IF(I20=N20,M20,I20),I20) | J21: =IF(D20="Aceptado",IF(J20=N20,M20,J20),J20) | K21: =IF(D20="Aceptado",IF(K20=N20,M20,K20),K20) | L21: =IF(D20="Aceptado",IF(L20=N20,M20,L20),L20) | M21: =K21 | N21: =L21 | O21: =IF(D21="Aceptado",O20+C21,O20)
A22: 19 | B22: x6 — x3 | C22: ='B-Matriz MI'!H9 | D22: =IF(M22=N22,"Rechazado","Aceptado") | E22: =IF(D22="Aceptado","","Ciclo: x6 y x3 ya conectados") | F22: =IF(D21="Aceptado",IF(F21=N21,M21,F21),F21) | G22: =IF(D21="Aceptado",IF(G21=N21,M21,G21),G21) | H22: =IF(D21="Aceptado",IF(H21=N21,M21,H21),H21) | I22: =IF(D21="Aceptado",IF(I21=N21,M21,I21),I21) | J22: =IF(D21="Aceptado",IF(J21=N21,M21,J21),J21) | K22: =IF(D21="Aceptado",IF(K21=N21,M21,K21),K21) | L22: =IF(D21="Aceptado",IF(L21=N21,M21,L21),L21) | M22: =J22 | N22: =L22 | O22: =IF(D22="Aceptado",O21+C22,O21)
A23: 20 | B23: x1 — x4 | C23: ='B-Matriz MI'!E5 | D23: =IF(M23=N23,"Rechazado","Aceptado") | E23: =IF(D23="Aceptado","","Ciclo: x1 y x4 ya conectados") | F23: =IF(D22="Aceptado",IF(F22=N22,M22,F22),F22) | G23: =IF(D22="Aceptado",IF(G22=N22,M22,G22),G22) | H23: =IF(D22="Aceptado",IF(H22=N22,M22,H22),H22) | I23: =IF(D22="Aceptado",IF(I22=N22,M22,I22),I22) | J23: =IF(D22="Aceptado",IF(J22=N22,M22,J22),J22) | K23: =IF(D22="Aceptado",IF(K22=N22,M22,K22),K22) | L23: =IF(D22="Aceptado",IF(L22=N22,M22,L22),L22) | M23: =F23 | N23: =I23 | O23: =IF(D23="Aceptado",O22+C23,O22)
A24: 21 | B24: x4 — x3 | C24: ='B-Matriz MI'!H8 | D24: =IF(M24=N24,"Rechazado","Aceptado") | E24: =IF(D24="Aceptado","","Ciclo: x4 y x3 ya conectados") | F24: =IF(D23="Aceptado",IF(F23=N23,M23,F23),F23) | G24: =IF(D23="Aceptado",IF(G23=N23,M23,G23),G23) | H24: =IF(D23="Aceptado",IF(H23=N23,M23,H23),H23) | I24: =IF(D23="Aceptado",IF(I23=N23,M23,I23),I23) | J24: =IF(D23="Aceptado",IF(J23=N23,M23,J23),J23) | K24: =IF(D23="Aceptado",IF(K23=N23,M23,K23),K23) | L24: =IF(D23="Aceptado",IF(L23=N23,M23,L23),L23) | M24: =I24 | N24: =L24 | O24: =IF(D24="Aceptado",O23+C24,O23)

Sheet B-Prim
A1: Dataset B — Algoritmo de Prim (desde x5)
A3: Paso | B3: Arista | C3: Peso IM | D3: Origen→Destino | E3: Visitados | F3: Acum
A4: Paso 1 | B4: x5 — x2 | C4: 0.6555 | D4: x5 → x2 | E4: {x2, x5} | F4: 0.6555
A5: Paso 2 | B5: x5 — x1 | C5: 0.415 | D5: x5 → x1 | E5: {x2, x5, x1} | F5: 1.0704
A6: Paso 3 | B6: x5 — x9 | C6: 0.0162 | D6: x5 → x9 | E6: {x9, x2, x5, x1} | F6: 1.0866
A7: Paso 4 | B7: x9 — x6 | C7: 0.9974 | D7: x9 → x6 | E7: {x2, x6, x1, x9, x5} | F7: 2.084
A8: Paso 5 | B8: x9 — x4 | C8: 0.7475 | D8: x9 → x4 | E8: {x4, x2, x6, x1, x9, x5} | F8: 2.8315
A9: Paso 6 | B9: x1 — x3 | C9: 0.0022 | D9: x1 → x3 | E9: {x4, x2, x6, x1, x3, x9, x5} | F9: 2.8337
A11: PESO TOTAL MST (Prim) | F11: 2.8337

Sheet B-MST Resumen
A1: Dataset B — MST Resumen
A3: # | B3: Arista | C3: Peso IM | D3: Acumulado
A4: 1 | B4: x6 — x9 | C4: 0.9974 | D4: 0.9974
A5: 2 | B5: x4 — x9 | C5: 0.7475 | D5: 1.7449
A6: 3 | B6: x2 — x5 | C6: 0.6555 | D6: 2.4003
A7: 4 | B7: x1 — x5 | C7: 0.415 | D7: 2.8153
A8: 5 | B8: x5 — x9 | C8: 0.0162 | D8: 2.8315
A9: 6 | B9: x1 — x3 | C9: 0.0022 | D9: 2.8337
A11: PESO TOTAL MST | C11: 2.8337

Sheet Rutas MST A
A1: Matriz de Distancias de Caminos - Dataset A (x7=0)
A3: d(i,j) | B3: x1 | C3: x2 | D3: x3 | E3: x4 | F3: x5 | G3: x6 | H3: x9 | I3: Suma fila
A4: x1 | B4: 0 | C4: 1.1106 | D4: 0.4364 | E4: 1.1166 | F4: 0.4237 | G4: 1.4304 | H4: 0.4306 | I4: =SUM(B4:H4)
A5: x2 | B5: 1.1106 | C5: 0 | D5: 0.6996 | E5: 1.3798 | F5: 0.6869 | G5: 1.6936 | H5: 0.6938 | I5: =SUM(B5:H5)
A6: x3 | B6: 0.4364 | C6: 0.6996 | D6: 0 | E6: 0.6918 | F6: 0.0127 | G6: 1.0056 | H6: 0.0058 | I6: =SUM(B6:H6)
A7: x4 | B7: 1.1166 | C7: 1.3798 | D7: 0.6918 | E7: 0 | F7: 0.6929 | G7: 1.6858 | H7: 0.686 | I7: =SUM(B7:H7)
A8: x5 | B8: 0.4237 | C8: 0.6869 | D8: 0.0127 | E8: 0.6929 | F8: 0 | G8: 1.0067 | H8: 0.0069 | I8: =SUM(B8:H8)
A9: x6 | B9: 1.4304 | C9: 1.6936 | D9: 1.0056 | E9: 1.6858 | F9: 1.0067 | G9: 0 | H9: 0.9998 | I9: =SUM(B9:H9)
A10: x9 | B10: 0.4306 | C10: 0.6938 | D10: 0.0058 | E10: 0.686 | F10: 0.0069 | G10: 0.9998 | H10: 0 | I10: =SUM(B10:H10)

Sheet Rutas MST B
A1: Matriz de Distancias de Caminos - Dataset B (x7=1)
A3: d(i,j) | B3: x1 | C3: x2 | D3: x3 | E3: x4 | F3: x5 | G3: x6 | H3: x9 | I3: Suma fila
A4: x1 | B4: 0 | C4: 1.0705 | D4: 0.0022 | E4: 1.1787 | F4: 0.415 | G4: 1.4286 | H4: 0.4312 | I4: =SUM(B4:H4)
A5: x2 | B5: 1.0705 | C5: 0 | D5: 1.0727 | E5: 1.4192 | F5: 0.6555 | G5: 1.6691 | H5: 0.6717 | I5: =SUM(B5:H5)
A6: x3 | B6: 0.0022 | C6: 1.0727 | D6: 0 | E6: 1.1809 | F6: 0.4172 | G6: 1.4308 | H6: 0.4334 | I6: =SUM(B6:H6)
A7: x4 | B7: 1.1787 | C7: 1.4192 | D7: 1.1809 | E7: 0 | F7: 0.7637 | G7: 1.7449 | H7: 0.7475 | I7: =SUM(B7:H7)
A8: x5 | B8: 0.415 | C8: 0.6555 | D8: 0.4172 | E8: 0.7637 | F8: 0 | G8: 1.0136 | H8: 0.0162 | I8: =SUM(B8:H8)
A9: x6 | B9: 1.4286 | C9: 1.6691 | D9: 1.4308 | E9: 1.7449 | F9: 1.0136 | G9: 0 | H9: 0.9974 | I9: =SUM(B9:H9)
A10: x9 | B10: 0.4312 | C10: 0.6717 | D10: 0.4334 | E10: 0.7475 | F10: 0.0162 | G10: 0.9974 | H10: 0 | I10: =SUM(B10:H10)

Sheet Sensibilidad rVP
A1: Analisis de Sensibilidad - Metodo rVP (Rango de Variacion Permitido)
A2: D = Suma_A - Suma_B | Variable critica si |D| > 0.5
A4: Variable | B4: Suma_A (Dataset A) | C4: Suma_B (Dataset B) | D4: D = Suma_A - Suma_B | E4: |D| | F4: Critica?
A5: x1 | B5: ='Rutas MST A'!I4 | C5: ='Rutas MST B'!I4 | D5: =B5-C5 | E5: =ABS(D5) | F5: =IF(E5>0.5,"Si","No")
A6: x2 | B6: ='Rutas MST A'!I5 | C6: ='Rutas MST B'!I5 | D6: =B6-C6 | E6: =ABS(D6) | F6: =IF(E6>0.5,"Si","No")
A7: x3 | B7: ='Rutas MST A'!I6 | C7: ='Rutas MST B'!I6 | D7: =B7-C7 | E7: =ABS(D7) | F7: =IF(E7>0.5,"Si","No")
A8: x4 | B8: ='Rutas MST A'!I7 | C8: ='Rutas MST B'!I7 | D8: =B8-C8 | E8: =ABS(D8) | F8: =IF(E8>0.5,"Si","No")
A9: x5 | B9: ='Rutas MST A'!I8 | C9: ='Rutas MST B'!I8 | D9: =B9-C9 | E9: =ABS(D9) | F9: =IF(E9>0.5,"Si","No")
A10: x6 | B10: ='Rutas MST A'!I9 | C10: ='Rutas MST B'!I9 | D10: =B10-C10 | E10: =ABS(D10) | F10: =IF(E10>0.5,"Si","No")
A11: x9 | B11: ='Rutas MST A'!I10 | C11: ='Rutas MST B'!I10 | D11: =B11-C11 | E11: =ABS(D11) | F11: =IF(E11>0.5,"Si","No")
